Workbook
Name a: #REF!

Sheet BASE
A1: COD_FUNCIONARIO | B1: NOME | C1: DATA_ADMISSAO | D1: SITUACAO | E1: RE_GESTOR | F1: NOME_GESTOR | G1: ESCALA | H1: DEPARTAMENTO | I1: OBJ_CUSTO_FUNC | J1: COD_CARGO | K1: CARGO | L1: COD_CURSO_REQUISITO | M1: TIPO | N1: DESCRICAO | O1: NOTA | P1: STATUS | Q1: EMPRESA | R1: FILIAL | S1: SETOR | T1: NOME_SETOR | U1: DATA_CURSO | V1: TIPO_RENOVACAO | W1: VENCIDO | X1: STATUS_GERAL | Y1: FILIAL_NOME | Z1: TRILHA DE TREINAMENTO | AA1: TREINAMENTO_STATUS_GERAL
A2: 3 | B2: GABRIEL JOSE FRANCISCO SANTOS | C2: 43683 | D2: NORMAL | E2: 5 | F2: GABRIEL DA SILVA OLIVEIRA BROCHADO | G2: 801 - 06:00 AS 18:00 4-3 E 3-4 A1 | H2: EXPORTAÇÃO | I2: 134 | J2: 5076 | K2: OPERADOR MAQUINAS AUTOPROPELIDAS | L2: 123 | M2: CURSO | N2: NR 20 - SEG. E TRAB. INFLAMÁVEIS E COMBUSTIVEIS CLASSE III - BASICO | P2: Concluido | Q2: 1 | R2: 1 | S2: 78 | T2: ADMINISTRAÇÃO | U2: 45243 | V2: TRIENAL | W2: -384 | X2: =IF(Tabela1[[#This Row],[DATA_CURSO]]="", "PENDENTE", IF(Tabela1[[#This Row],[TIPO_RENOVACAO]]="QUANDO NECESSARIO", "EM DIA – não é necessário renovar", IFERROR( IF(SUM(Tabela1[[#This Row],[DATA_CURSO]],VLOOKUP(Tabela1[[#This Row],[DESCRICAO]],RENOVAÇÃO!A:C,3,0))<TODAY(), "VENCIDO – "&TEXT(SUM(Tabela1[[#This Row],[DATA_CURSO]],VLOOKUP(Tabela1[[#This Row],[DESCRICAO]],RENOVAÇÃO!A:C,3,0)),"dd/mm/aa"), "EM DIA – vence em "&TEXT(SUM(Tabela1[[#This Row],[DATA_CURSO]],VLOOKUP(Tabela1[[#This Row],[DESCRICAO]],RENOVAÇÃO!A:C,3,0)),"dd/mm/aa")), "NÃO É NECESSÁRIO RENOVAR"))) -> EM DIA – vence em 12/11/26 | Y2: =IF(Tabela1[[#This Row],[FILIAL]]=1,"SINOP",IF(Tabela1[[#This Row],[FILIAL]]=2,"DOURADOS",IF(Tabela1[[#This Row],[FILIAL]]=3,"NOVA MUTUM",IF(Tabela1[[#This Row],[FILIAL]]=4,"FULLING",IF(Tabela1[[#This Row],[FILIAL]]=5,"SÃO PAULO",IF(Tabela1[[#This Row],[FILIAL]]=6,"SIDROLÂNDIA",IF(Tabela1[[#This Row],[FILIAL]]=8,"BALSAS",IF(Tabela1[[#This Row],[FILIAL]]=10,"LUIS EDUARDO MAGALHÃES","")))))))) -> SINOP | Z2: =VLOOKUP(N2,RENOVAÇÃO!A:D,4,0) -> TRILHA SEGURANÇA DO TRABALHO | AA2: =CONCATENATE("• ", Tabela1[[#This Row],[DESCRICAO]], " - ",Tabela1[[#This Row],[STATUS_GERAL]]) -> • NR 20 - SEG. E TRAB. INFLAMÁVEIS E COMBUSTIVEIS CLASSE III - BASICO - EM DIA – vence em 12/11/26
A3: 3 | B3: GABRIEL JOSE FRANCISCO SANTOS | C3: 43683 | D3: NORMAL | E3: 5 | F3: GABRIEL DA SILVA OLIVEIRA BROCHADO | G3: 801 - 06:00 AS 18:00 4-3 E 3-4 A1 | H3: EXPORTAÇÃO | I3: 134 | J3: 5076 | K3: OPERADOR MAQUINAS AUTOPROPELIDAS | L3: 266 | M3: CURSO | N3: NR 20 - SEG. E TRAB. INFLAMÁVEIS E COMBUSTIVEIS CLASSE III - INTERMEDIÁRIO | P3: Concluido | Q3: 1 | R3: 1 | S3: 80 | T3: MANUTENÇÃO INDUSTRIAL | U3: 45812 | V3: BIENAL | W3: -588 | X3: =IF(Tabela1[[#This Row],[DATA_CURSO]]="", "PENDENTE", IF(Tabela1[[#This Row],[TIPO_RENOVACAO]]="QUANDO NECESSARIO", "EM DIA – não é necessário renovar", IFERROR( IF(SUM(Tabela1[[#This Row],[DATA_CURSO]],VLOOKUP(Tabela1[[#This Row],[DESCRICAO]],RENOVAÇÃO!A:C,3,0))<TODAY(), "VENCIDO – "&TEXT(SUM(Tabela1[[#This Row],[DATA_CURSO]],VLOOKUP(Tabela1[[#This Row],[DESCRICAO]],RENOVAÇÃO!A:C,3,0)),"dd/mm/aa"), "EM DIA – vence em "&TEXT(SUM(Tabela1[[#This Row],[DATA_CURSO]],VLOOKUP(Tabela1[[#This Row],[DESCRICAO]],RENOVAÇÃO!A:C,3,0)),"dd/mm/aa")), "NÃO É NECESSÁRIO RENOVAR"))) -> EM DIA – vence em 04/06/27 | Y3: =IF(Tabela1[[#This Row],[FILIAL]]=1,"SINOP",IF(Tabela1[[#This Row],[FILIAL]]=2,"DOURADOS",IF(Tabela1[[#This Row],[FILIAL]]=3,"NOVA MUTUM",IF(Tabela1[[#This Row],[FILIAL]]=4,"FULLING",IF(Tabela1[[#This Row],[FILIAL]]=5,"SÃO PAULO",IF(Tabela1[[#This Row],[FILIAL]]=6,"SIDROLÂNDIA",IF(Tabela1[[#This Row],[FILIAL]]=8,"BALSAS",IF(Tabela1[[#This Row],[FILIAL]]=10,"LUIS EDUARDO MAGALHÃES","")))))))) -> SINOP | Z3: =VLOOKUP(N3,RENOVAÇÃO!A:D,4,0) -> TRILHA SEGURANÇA DO TRABALHO | AA3: =CONCATENATE("• ", Tabela1[[#This Row],[DESCRICAO]], " - ",Tabela1[[#This Row],[STATUS_GERAL]]) -> • NR 20 - SEG. E TRAB. INFLAMÁVEIS E COMBUSTIVEIS CLASSE III - INTERMEDIÁRIO - EM DIA – vence em 04/06/27
A4: 3 | B4: GABRIEL JOSE FRANCISCO SANTOS | C4: 43683 | D4: NORMAL | E4: 5 | F4: GABRIEL DA SILVA OLIVEIRA BROCHADO | G4: 801 - 06:00 AS 18:00 4-3 E 3-4 A1 | H4: EXPORTAÇÃO | I4: 134 | J4: 5076 | K4: OPERADOR MAQUINAS AUTOPROPELIDAS | L4: 28 | M4: CURSO | N4: NR 35 - TRABALHO EM ALTURA | P4: Concluido | Q4: 1 | R4: 1 | S4: 80 | T4: MANUTENÇÃO INDUSTRIAL | U4: 45349 | V4: BIENAL | W4: -125 | X4: =IF(Tabela1[[#This Row],[DATA_CURSO]]="", "PENDENTE", IF(Tabela1[[#This Row],[TIPO_RENOVACAO]]="QUANDO NECESSARIO", "EM DIA – não é necessário renovar", IFERROR( IF(SUM(Tabela1[[#This Row],[DATA_CURSO]],VLOOKUP(Tabela1[[#This Row],[DESCRICAO]],RENOVAÇÃO!A:C,3,0))<TODAY(), "VENCIDO – "&TEXT(SUM(Tabela1[[#This Row],[DATA_CURSO]],VLOOKUP(Tabela1[[#This Row],[DESCRICAO]],RENOVAÇÃO!A:C,3,0)),"dd/mm/aa"), "EM DIA – vence em "&TEXT(SUM(Tabela1[[#This Row],[DATA_CURSO]],VLOOKUP(Tabela1[[#This Row],[DESCRICAO]],RENOVAÇÃO!A:C,3,0)),"dd/mm/aa")), "NÃO É NECESSÁRIO RENOVAR"))) -> EM DIA – vence em 26/02/26 | Y4: =IF(Tabela1[[#This Row],[FILIAL]]=1,"SINOP",IF(Tabela1[[#This Row],[FILIAL]]=2,"DOURADOS",IF(Tabela1[[#This Row],[FILIAL]]=3,"NOVA MUTUM",IF(Tabela1[[#This Row],[FILIAL]]=4,"FULLING",IF(Tabela1[[#This Row],[FILIAL]]=5,"SÃO PAULO",IF(Tabela1[[#This Row],[FILIAL]]=6,"SIDROLÂNDIA",IF(Tabela1[[#This Row],[FILIAL]]=8,"BALSAS",IF(Tabela1[[#This Row],[FILIAL]]=10,"LUIS EDUARDO MAGALHÃES","")))))))) -> SINOP | Z4: =VLOOKUP(N4,RENOVAÇÃO!A:D,4,0) -> TRILHA SEGURANÇA DO TRABALHO | AA4: =CONCATENATE("• ", Tabela1[[#This Row],[DESCRICAO]], " - ",Tabela1[[#This Row],[STATUS_GERAL]]) -> • NR 35 - TRABALHO EM ALTURA - EM DIA – vence em 26/02/26
A5: 3 | B5: GABRIEL JOSE FRANCISCO SANTOS | C5: 43683 | D5: NORMAL | E5: 5 | F5: GABRIEL DA SILVA OLIVEIRA BROCHADO | G5: 801 - 06:00 AS 18:00 4-3 E 3-4 A1 | H5: EXPORTAÇÃO | I5: 134 | J5: 5076 | K5: OPERADOR MAQUINAS AUTOPROPELIDAS | L5: 10 | M5: CURSO | N5: NR 33 - SEGURANÇA E SAUDE NOS TRABALHOS EM ESPAÇOS CONFINADOS - VIGIA E TRABALHADOR | P5: Concluido | Q5: 1 | R5: 1 | S5: 80 | T5: MANUTENÇÃO INDUSTRIAL | U5: 44333 | V5: ANUAL | W5: 1256 | X5: =IF(Tabela1[[#This Row],[DATA_CURSO]]="", "PENDENTE", IF(Tabela1[[#This Row],[TIPO_RENOVACAO]]="QUANDO NECESSARIO", "EM DIA – não é necessário renovar", IFERROR( IF(SUM(Tabela1[[#This Row],[DATA_CURSO]],VLOOKUP(Tabela1[[#This Row],[DESCRICAO]],RENOVAÇÃO!A:C,3,0))<TODAY(), "VENCIDO – "&TEXT(SUM(Tabela1[[#This Row],[DATA_CURSO]],VLOOKUP(Tabela1[[#This Row],[DESCRICAO]],RENOVAÇÃO!A:C,3,0)),"dd/mm/aa"), "EM DIA – vence em "&TEXT(SUM(Tabela1[[#This Row],[DATA_CURSO]],VLOOKUP(Tabela1[[#This Row],[DESCRICAO]],RENOVAÇÃO!A:C,3,0)),"dd/mm/aa")), "NÃO É NECESSÁRIO RENOVAR"))) -> VENCIDO – 17/05/22 | Y5: =IF(Tabela1[[#This Row],[FILIAL]]=1,"SINOP",IF(Tabela1[[#This Row],[FILIAL]]=2,"DOURADOS",IF(Tabela1[[#This Row],[FILIAL]]=3,"NOVA MUTUM",IF(Tabela1[[#This Row],[FILIAL]]=4,"FULLING",IF(Tabela1[[#This Row],[FILIAL]]=5,"SÃO PAULO",IF(Tabela1[[#This Row],[FILIAL]]=6,"SIDROLÂNDIA",IF(Tabela1[[#This Row],[FILIAL]]=8,"BALSAS",IF(Tabela1[[#This Row],[FILIAL]]=10,"LUIS EDUARDO MAGALHÃES","")))))))) -> SINOP | Z5: =VLOOKUP(N5,RENOVAÇÃO!A:D,4,0) -> TRILHA SEGURANÇA DO TRABALHO | AA5: =CONCATENATE("• ", Tabela1[[#This Row],[DESCRICAO]], " - ",Tabela1[[#This Row],[STATUS_GERAL]]) -> • NR 33 - SEGURANÇA E SAUDE NOS TRABALHOS EM ESPAÇOS CONFINADOS - VIGIA E TRABALHADOR - VENCIDO – 17/05/22
A6: 3 | B6: GABRIEL JOSE FRANCISCO SANTOS | C6: 43683 | D6: NORMAL | E6: 5 | F6: GABRIEL DA SILVA OLIVEIRA BROCHADO | G6: 801 - 06:00 AS 18:00 4-3 E 3-4 A1 | H6: EXPORTAÇÃO | I6: 134 | J6: 5076 | K6: OPERADOR MAQUINAS AUTOPROPELIDAS | L6: 262 | M6: CURSO | N6: NR 11 - OPERADOR PA CARREGADEIRA | P6: Concluido | Q6: 1 | R6: 1 | S6: 114 | T6: OPERAÇÕES | U6: 45871 | V6: BIENAL | W6: -647 | X6: =IF(Tabela1[[#This Row],[DATA_CURSO]]="", "PENDENTE", IF(Tabela1[[#This Row],[TIPO_RENOVACAO]]="QUANDO NECESSARIO", "EM DIA – não é necessário renovar", IFERROR( IF(SUM(Tabela1[[#This Row],[DATA_CURSO]],VLOOKUP(Tabela1[[#This Row],[DESCRICAO]],RENOVAÇÃO!A:C,3,0))<TODAY(), "VENCIDO – "&TEXT(SUM(Tabela1[[#This Row],[DATA_CURSO]],VLOOKUP(Tabela1[[#This Row],[DESCRICAO]],RENOVAÇÃO!A:C,3,0)),"dd/mm/aa"), "EM DIA – vence em "&TEXT(SUM(Tabela1[[#This Row],[DATA_CURSO]],VLOOKUP(Tabela1[[#This Row],[DESCRICAO]],RENOVAÇÃO!A:C,3,0)),"dd/mm/aa")), "NÃO É NECESSÁRIO RENOVAR"))) -> EM DIA – vence em 02/08/27 | Y6: =IF(Tabela1[[#This Row],[FILIAL]]=1,"SINOP",IF(Tabela1[[#This Row],[FILIAL]]=2,"DOURADOS",IF(Tabela1[[#This Row],[FILIAL]]=3,"NOVA MUTUM",IF(Tabela1[[#This Row],[FILIAL]]=4,"FULLING",IF(Tabela1[[#This Row],[FILIAL]]=5,"SÃO PAULO",IF(Tabela1[[#This Row],[FILIAL]]=6,"SIDROLÂNDIA",IF(Tabela1[[#This Row],[FILIAL]]=8,"BALSAS",IF(Tabela1[[#This Row],[FILIAL]]=10,"LUIS EDUARDO MAGALHÃES","")))))))) -> SINOP | Z6: =VLOOKUP(N6,RENOVAÇÃO!A:D,4,0) -> TRILHA SEGURANÇA DO TRABALHO | AA6: =CONCATENATE("• ", Tabela1[[#This Row],[DESCRICAO]], " - ",Tabela1[[#This Row],[STATUS_GERAL]]) -> • NR 11 - OPERADOR PA CARREGADEIRA - EM DIA – vence em 02/08/27
A7: 3 | B7: GABRIEL JOSE FRANCISCO SANTOS | C7: 43683 | D7: NORMAL | E7: 5 | F7: GABRIEL DA SILVA OLIVEIRA BROCHADO | G7: 801 - 06:00 AS 18:00 4-3 E 3-4 A1 | H7: EXPORTAÇÃO | I7: 134 | J7: 5076 | K7: OPERADOR MAQUINAS AUTOPROPELIDAS | L7: 8 | M7: CURSO | N7: NR 35 - TRABALHO EM ALTURA | P7: Concluido | Q7: 1 | R7: 3 | S7: 102 | T7: PROCESSO INDUSTRIAL | U7: 45581 | V7: BIENAL | W7: -357 | X7: =IF(Tabela1[[#This Row],[DATA_CURSO]]="", "PENDENTE", IF(Tabela1[[#This Row],[TIPO_RENOVACAO]]="QUANDO NECESSARIO", "EM DIA – não é necessário renovar", IFERROR( IF(SUM(Tabela1[[#This Row],[DATA_CURSO]],VLOOKUP(Tabela1[[#This Row],[DESCRICAO]],RENOVAÇÃO!A:C,3,0))<TODAY(), "VENCIDO – "&TEXT(SUM(Tabela1[[#This Row],[DATA_CURSO]],VLOOKUP(Tabela1[[#This Row],[DESCRICAO]],RENOVAÇÃO!A:C,3,0)),"dd/mm/aa"), "EM DIA – vence em "&TEXT(SUM(Tabela1[[#This Row],[DATA_CURSO]],VLOOKUP(Tabela1[[#This Row],[DESCRICAO]],RENOVAÇÃO!A:C,3,0)),"dd/mm/aa")), "NÃO É NECESSÁRIO RENOVAR"))) -> EM DIA – vence em 16/10/26 | Y7: =IF(Tabela1[[#This Row],[FILIAL]]=1,"SINOP",IF(Tabela1[[#This Row],[FILIAL]]=2,"DOURADOS",IF(Tabela1[[#This Row],[FILIAL]]=3,"NOVA MUTUM",IF(Tabela1[[#This Row],[FILIAL]]=4,"FULLING",IF(Tabela1[[#This Row],[FILIAL]]=5,"SÃO PAULO",IF(Tabela1[[#This Row],[FILIAL]]=6,"SIDROLÂNDIA",IF(Tabela1[[#This Row],[FILIAL]]=8,"BALSAS",IF(Tabela1[[#This Row],[FILIAL]]=10,"LUIS EDUARDO MAGALHÃES","")))))))) -> NOVA MUTUM | Z7: =VLOOKUP(N7,RENOVAÇÃO!A:D,4,0) -> TRILHA SEGURANÇA DO TRABALHO | AA7: =CONCATENATE("• ", Tabela1[[#This Row],[DESCRICAO]], " - ",Tabela1[[#This Row],[STATUS_GERAL]]) -> • NR 35 - TRABALHO EM ALTURA - EM DIA – vence em 16/10/26
A8: 3 | B8: GABRIEL JOSE FRANCISCO SANTOS | C8: 43683 | D8: NORMAL | E8: 5 | F8: GABRIEL DA SILVA OLIVEIRA BROCHADO | G8: 801 - 06:00 AS 18:00 4-3 E 3-4 A1 | H8: EXPORTAÇÃO | I8: 134 | J8: 5076 | K8: OPERADOR MAQUINAS AUTOPROPELIDAS | L8: 1 | M8: CURSO | N8: BLOQUEIO E SINALIZAÇÃO DE ENERGIAS PERIGOSAS - LOCKOUT/TAGOUT - NR10 E NR12 | P8: Concluido | Q8: 1 | R8: 3 | S8: 102 | T8: PROCESSO INDUSTRIAL | U8: 44820 | V8: QUANDO NECESSARIO | X8: =IF(Tabela1[[#This Row],[DATA_CURSO]]="", "PENDENTE", IF(Tabela1[[#This Row],[TIPO_RENOVACAO]]="QUANDO NECESSARIO", "EM DIA – não é necessário renovar", IFERROR( IF(SUM(Tabela1[[#This Row],[DATA_CURSO]],VLOOKUP(Tabela1[[#This Row],[DESCRICAO]],RENOVAÇÃO!A:C,3,0))<TODAY(), "VENCIDO – "&TEXT(SUM(Tabela1[[#This Row],[DATA_CURSO]],VLOOKUP(Tabela1[[#This Row],[DESCRICAO]],RENOVAÇÃO!A:C,3,0)),"dd/mm/aa"), "EM DIA – vence em "&TEXT(SUM(Tabela1[[#This Row],[DATA_CURSO]],VLOOKUP(Tabela1[[#This Row],[DESCRICAO]],RENOVAÇÃO!A:C,3,0)),"dd/mm/aa")), "NÃO É NECESSÁRIO RENOVAR"))) -> EM DIA – não é necessário renovar | Y8: =IF(Tabela1[[#This Row],[FILIAL]]=1,"SINOP",IF(Tabela1[[#This Row],[FILIAL]]=2,"DOURADOS",IF(Tabela1[[#This Row],[FILIAL]]=3,"NOVA MUTUM",IF(Tabela1[[#This Row],[FILIAL]]=4,"FULLING",IF(Tabela1[[#This Row],[FILIAL]]=5,"SÃO PAULO",IF(Tabela1[[#This Row],[FILIAL]]=6,"SIDROLÂNDIA",IF(Tabela1[[#This Row],[FILIAL]]=8,"BALSAS",IF(Tabela1[[#This Row],[FILIAL]]=10,"LUIS EDUARDO MAGALHÃES","")))))))) -> NOVA MUTUM | Z8: =VLOOKUP(N8,RENOVAÇÃO!A:D,4,0) -> TRILHA SEGURANÇA DO TRABALHO | AA8: =CONCATENATE("• ", Tabela1[[#This Row],[DESCRICAO]], " - ",Tabela1[[#This Row],[STATUS_GERAL]]) -> • BLOQUEIO E SINALIZAÇÃO DE ENERGIAS PERIGOSAS - LOCKOUT/TAGOUT - NR10 E NR12 - EM DIA – não é necessário renovar
A9: 3 | B9: GABRIEL JOSE FRANCISCO SANTOS | C9: 43683 | D9: NORMAL | E9: 5 | F9: GABRIEL DA SILVA OLIVEIRA BROCHADO | G9: 801 - 06:00 AS 18:00 4-3 E 3-4 A1 | H9: EXPORTAÇÃO | I9: 134 | J9: 5076 | K9: OPERADOR MAQUINAS AUTOPROPELIDAS | L9: 308 | M9: CURSO | N9: NR 35 - TRABALHO EM ALTURA | P9: Concluido | Q9: 1 | R9: 1 | S9: 102 | T9: PROCESSO INDUSTRIAL | U9: 45350 | V9: BIENAL | W9: -126 | X9: =IF(Tabela1[[#This Row],[DATA_CURSO]]="", "PENDENTE", IF(Tabela1[[#This Row],[TIPO_RENOVACAO]]="QUANDO NECESSARIO", "EM DIA – não é necessário renovar", IFERROR( IF(SUM(Tabela1[[#This Row],[DATA_CURSO]],VLOOKUP(Tabela1[[#This Row],[DESCRICAO]],RENOVAÇÃO!A:C,3,0))<TODAY(), "VENCIDO – "&TEXT(SUM(Tabela1[[#This Row],[DATA_CURSO]],VLOOKUP(Tabela1[[#This Row],[DESCRICAO]],RENOVAÇÃO!A:C,3,0)),"dd/mm/aa"), "EM DIA – vence em "&TEXT(SUM(Tabela1[[#This Row],[DATA_CURSO]],VLOOKUP(Tabela1[[#This Row],[DESCRICAO]],RENOVAÇÃO!A:C,3,0)),"dd/mm/aa")), "NÃO É NECESSÁRIO RENOVAR"))) -> EM DIA – vence em 27/02/26 | Y9: =IF(Tabela1[[#This Row],[FILIAL]]=1,"SINOP",IF(Tabela1[[#This Row],[FILIAL]]=2,"DOURADOS",IF(Tabela1[[#This Row],[FILIAL]]=3,"NOVA MUTUM",IF(Tabela1[[#This Row],[FILIAL]]=4,"FULLING",IF(Tabela1[[#This Row],[FILIAL]]=5,"SÃO PAULO",IF(Tabela1[[#This Row],[FILIAL]]=6,"SIDROLÂNDIA",IF(Tabela1[[#This Row],[FILIAL]]=8,"BALSAS",IF(Tabela1[[#This Row],[FILIAL]]=10,"LUIS EDUARDO MAGALHÃES","")))))))) -> SINOP | Z9: =VLOOKUP(N9,RENOVAÇÃO!A:D,4,0) -> TRILHA SEGURANÇA DO TRABALHO | AA9: =CONCATENATE("• ", Tabela1[[#This Row],[DESCRICAO]], " - ",Tabela1[[#This Row],[STATUS_GERAL]]) -> • NR 35 - TRABALHO EM ALTURA - EM DIA – vence em 27/02/26
A10: 3 | B10: GABRIEL JOSE FRANCISCO SANTOS | C10: 43683 | D10: NORMAL | E10: 5 | F10: GABRIEL DA SILVA OLIVEIRA BROCHADO | G10: 801 - 06:00 AS 18:00 4-3 E 3-4 A1 | H10: EXPORTAÇÃO | I10: 134 | J10: 5076 | K10: OPERADOR MAQUINAS AUTOPROPELIDAS | L10: 321 | M10: CURSO | N10: NR 20 - SEG. E TRAB. INFLAMÁVEIS E COMBUSTIVEIS CLASSE III - INTERMEDIÁRIO | P10: Concluido | Q10: 1 | R10: 6 | S10: 80 | T10: MANUTENÇÃO INDUSTRIAL | U10: 45693 | V10: BIENAL | W10: -469 | X10: =IF(Tabela1[[#This Row],[DATA_CURSO]]="", "PENDENTE", IF(Tabela1[[#This Row],[TIPO_RENOVACAO]]="QUANDO NECESSARIO", "EM DIA – não é necessário renovar", IFERROR( IF(SUM(Tabela1[[#This Row],[DATA_CURSO]],VLOOKUP(Tabela1[[#This Row],[DESCRICAO]],RENOVAÇÃO!A:C,3,0))<TODAY(), "VENCIDO – "&TEXT(SUM(Tabela1[[#This Row],[DATA_CURSO]],VLOOKUP(Tabela1[[#This Row],[DESCRICAO]],RENOVAÇÃO!A:C,3,0)),"dd/mm/aa"), "EM DIA – vence em "&TEXT(SUM(Tabela1[[#This Row],[DATA_CURSO]],VLOOKUP(Tabela1[[#This Row],[DESCRICAO]],RENOVAÇÃO!A:C,3,0)),"dd/mm/aa")), "NÃO É NECESSÁRIO RENOVAR"))) -> EM DIA – vence em 05/02/27 | Y10: =IF(Tabela1[[#This Row],[FILIAL]]=1,"SINOP",IF(Tabela1[[#This Row],[FILIAL]]=2,"DOURADOS",IF(Tabela1[[#This Row],[FILIAL]]=3,"NOVA MUTUM",IF(Tabela1[[#This Row],[FILIAL]]=4,"FULLING",IF(Tabela1[[#This Row],[FILIAL]]=5,"SÃO PAULO",IF(Tabela1[[#This Row],[FILIAL]]=6,"SIDROLÂNDIA",IF(Tabela1[[#This Row],[FILIAL]]=8,"BALSAS",IF(Tabela1[[#This Row],[FILIAL]]=10,"LUIS EDUARDO MAGALHÃES","")))))))) -> SIDROLÂNDIA | Z10: =VLOOKUP(N10,RENOVAÇÃO!A:D,4,0) -> TRILHA SEGURANÇA DO TRABALHO | AA10: =CONCATENATE("• ", Tabela1[[#This Row],[DESCRICAO]], " - ",Tabela1[[#This Row],[STATUS_GERAL]]) -> • NR 20 - SEG. E TRAB. INFLAMÁVEIS E COMBUSTIVEIS CLASSE III - INTERMEDIÁRIO - EM DIA – vence em 05/02/27
A11: 3 | B11: GABRIEL JOSE FRANCISCO SANTOS | C11: 43683 | D11: NORMAL | E11: 5 | F11: GABRIEL DA SILVA OLIVEIRA BROCHADO | G11: 801 - 06:00 AS 18:00 4-3 E 3-4 A1 | H11: EXPORTAÇÃO | I11: 134 | J11: 5076 | K11: OPERADOR MAQUINAS AUTOPROPELIDAS | L11: 319 | M11: CURSO | N11: NR 26 - SINALIZAÇÃO DE SEGURANÇA | P11: Concluido | Q11: 1 | R11: 3 | S11: 102 | T11: PROCESSO INDUSTRIAL | U11: 45489 | V11: QUANDO NECESSARIO | X11: =IF(Tabela1[[#This Row],[DATA_CURSO]]="", "PENDENTE", IF(Tabela1[[#This Row],[TIPO_RENOVACAO]]="QUANDO NECESSARIO", "EM DIA – não é necessário renovar", IFERROR( IF(SUM(Tabela1[[#This Row],[DATA_CURSO]],VLOOKUP(Tabela1[[#This Row],[DESCRICAO]],RENOVAÇÃO!A:C,3,0))<TODAY(), "VENCIDO – "&TEXT(SUM(Tabela1[[#This Row],[DATA_CURSO]],VLOOKUP(Tabela1[[#This Row],[DESCRICAO]],RENOVAÇÃO!A:C,3,0)),"dd/mm/aa"), "EM DIA – vence em "&TEXT(SUM(Tabela1[[#This Row],[DATA_CURSO]],VLOOKUP(Tabela1[[#This Row],[DESCRICAO]],RENOVAÇÃO!A:C,3,0)),"dd/mm/aa")), "NÃO É NECESSÁRIO RENOVAR"))) -> EM DIA – não é necessário renovar | Y11: =IF(Tabela1[[#This Row],[FILIAL]]=1,"SINOP",IF(Tabela1[[#This Row],[FILIAL]]=2,"DOURADOS",IF(Tabela1[[#This Row],[FILIAL]]=3,"NOVA MUTUM",IF(Tabela1[[#This Row],[FILIAL]]=4,"FULLING",IF(Tabela1[[#This Row],[FILIAL]]=5,"SÃO PAULO",IF(Tabela1[[#This Row],[FILIAL]]=6,"SIDROLÂNDIA",IF(Tabela1[[#This Row],[FILIAL]]=8,"BALSAS",IF(Tabela1[[#This Row],[FILIAL]]=10,"LUIS EDUARDO MAGALHÃES","")))))))) -> NOVA MUTUM | Z11: =VLOOKUP(N11,RENOVAÇÃO!A:D,4,0) -> TRILHA SEGURANÇA DO TRABALHO | AA11: =CONCATENATE("• ", Tabela1[[#This Row],[DESCRICAO]], " - ",Tabela1[[#This Row],[STATUS_GERAL]]) -> • NR 26 - SINALIZAÇÃO DE SEGURANÇA - EM DIA – não é necessário renovar
A12: 3 | B12: GABRIEL JOSE FRANCISCO SANTOS | C12: 43683 | D12: NORMAL | E12: 5 | F12: GABRIEL DA SILVA OLIVEIRA BROCHADO | G12: 801 - 06:00 AS 18:00 4-3 E 3-4 A1 | H12: EXPORTAÇÃO | I12: 134 | J12: 5076 | K12: OPERADOR MAQUINAS AUTOPROPELIDAS | L12: 302 | M12: CURSO | N12: BLOQUEIO E SINALIZAÇÃO DE ENERGIAS PERIGOSAS - LOCKOUT/TAGOUT - NR10 E NR12 | P12: Concluido | Q12: 1 | R12: 3 | S12: 102 | T12: PROCESSO INDUSTRIAL | U12: 44878 | V12: QUANDO NECESSARIO | X12: =IF(Tabela1[[#This Row],[DATA_CURSO]]="", "PENDENTE", IF(Tabela1[[#This Row],[TIPO_RENOVACAO]]="QUANDO NECESSARIO", "EM DIA – não é necessário renovar", IFERROR( IF(SUM(Tabela1[[#This Row],[DATA_CURSO]],VLOOKUP(Tabela1[[#This Row],[DESCRICAO]],RENOVAÇÃO!A:C,3,0))<TODAY(), "VENCIDO – "&TEXT(SUM(Tabela1[[#This Row],[DATA_CURSO]],VLOOKUP(Tabela1[[#This Row],[DESCRICAO]],RENOVAÇÃO!A:C,3,0)),"dd/mm/aa"), "EM DIA – vence em "&TEXT(SUM(Tabela1[[#This Row],[DATA_CURSO]],VLOOKUP(Tabela1[[#This Row],[DESCRICAO]],RENOVAÇÃO!A:C,3,0)),"dd/mm/aa")), "NÃO É NECESSÁRIO RENOVAR"))) -> EM DIA – não é necessário renovar | Y12: =IF(Tabela1[[#This Row],[FILIAL]]=1,"SINOP",IF(Tabela1[[#This Row],[FILIAL]]=2,"DOURADOS",IF(Tabela1[[#This Row],[FILIAL]]=3,"NOVA MUTUM",IF(Tabela1[[#This Row],[FILIAL]]=4,"FULLING",IF(Tabela1[[#This Row],[FILIAL]]=5,"SÃO PAULO",IF(Tabela1[[#This Row],[FILIAL]]=6,"SIDROLÂNDIA",IF(Tabela1[[#This Row],[FILIAL]]=8,"BALSAS",IF(Tabela1[[#This Row],[FILIAL]]=10,"LUIS EDUARDO MAGALHÃES","")))))))) -> NOVA MUTUM | Z12: =VLOOKUP(N12,RENOVAÇÃO!A:D,4,0) -> TRILHA SEGURANÇA DO TRABALHO | AA12: =CONCATENATE("• ", Tabela1[[#This Row],[DESCRICAO]], " - ",Tabela1[[#This Row],[STATUS_GERAL]]) -> • BLOQUEIO E SINALIZAÇÃO DE ENERGIAS PERIGOSAS - LOCKOUT/TAGOUT - NR10 E NR12 - EM DIA – não é necessário renovar
A13: 3 | B13: GABRIEL JOSE FRANCISCO SANTOS | C13: 43683 | D13: NORMAL | E13: 5 | F13: GABRIEL DA SILVA OLIVEIRA BROCHADO | G13: 801 - 06:00 AS 18:00 4-3 E 3-4 A1 | H13: EXPORTAÇÃO | I13: 134 | J13: 5076 | K13: OPERADOR MAQUINAS AUTOPROPELIDAS | L13: 300 | M13: CURSO | N13: NR 35 - TRABALHO EM ALTURA | P13: Concluido | Q13: 1 | R13: 3 | S13: 102 | T13: PROCESSO INDUSTRIAL | U13: 45371 | V13: BIENAL | W13: -147 | X13: =IF(Tabela1[[#This Row],[DATA_CURSO]]="", "PENDENTE", IF(Tabela1[[#This Row],[TIPO_RENOVACAO]]="QUANDO NECESSARIO", "EM DIA – não é necessário renovar", IFERROR( IF(SUM(Tabela1[[#This Row],[DATA_CURSO]],VLOOKUP(Tabela1[[#This Row],[DESCRICAO]],RENOVAÇÃO!A:C,3,0))<TODAY(), "VENCIDO – "&TEXT(SUM(Tabela1[[#This Row],[DATA_CURSO]],VLOOKUP(Tabela1[[#This Row],[DESCRICAO]],RENOVAÇÃO!A:C,3,0)),"dd/mm/aa"), "EM DIA – vence em "&TEXT(SUM(Tabela1[[#This Row],[DATA_CURSO]],VLOOKUP(Tabela1[[#This Row],[DESCRICAO]],RENOVAÇÃO!A:C,3,0)),"dd/mm/aa")), "NÃO É NECESSÁRIO RENOVAR"))) -> EM DIA – vence em 20/03/26 | Y13: =IF(Tabela1[[#This Row],[FILIAL]]=1,"SINOP",IF(Tabela1[[#This Row],[FILIAL]]=2,"DOURADOS",IF(Tabela1[[#This Row],[FILIAL]]=3,"NOVA MUTUM",IF(Tabela1[[#This Row],[FILIAL]]=4,"FULLING",IF(Tabela1[[#This Row],[FILIAL]]=5,"SÃO PAULO",IF(Tabela1[[#This Row],[FILIAL]]=6,"SIDROLÂNDIA",IF(Tabela1[[#This Row],[FILIAL]]=8,"BALSAS",IF(Tabela1[[#This Row],[FILIAL]]=10,"LUIS EDUARDO MAGALHÃES","")))))))) -> NOVA MUTUM | Z13: =VLOOKUP(N13,RENOVAÇÃO!A:D,4,0) -> TRILHA SEGURANÇA DO TRABALHO | AA13: =CONCATENATE("• ", Tabela1[[#This Row],[DESCRICAO]], " - ",Tabela1[[#This Row],[STATUS_GERAL]]) -> • NR 35 - TRABALHO EM ALTURA - EM DIA – vence em 20/03/26
A14: 3 | B14: GABRIEL JOSE FRANCISCO SANTOS | C14: 43683 | D14: NORMAL | E14: 5 | F14: GABRIEL DA SILVA OLIVEIRA BROCHADO | G14: 801 - 06:00 AS 18:00 4-3 E 3-4 A1 | H14: EXPORTAÇÃO | I14: 134 | J14: 5076 | K14: OPERADOR MAQUINAS AUTOPROPELIDAS | L14: 295 | M14: CURSO | N14: NR 20 - SEG. E TRAB. INFLAMÁVEIS E COMBUSTIVEIS CLASSE III - AVANÇADO | P14: Concluido | Q14: 1 | R14: 10 | S14: 102 | T14: PROCESSO INDUSTRIAL | U14: 45390 | V14: ANUAL | W14: 199 | X14: =IF(Tabela1[[#This Row],[DATA_CURSO]]="", "PENDENTE", IF(Tabela1[[#This Row],[TIPO_RENOVACAO]]="QUANDO NECESSARIO", "EM DIA – não é necessário renovar", IFERROR( IF(SUM(Tabela1[[#This Row],[DATA_CURSO]],VLOOKUP(Tabela1[[#This Row],[DESCRICAO]],RENOVAÇÃO!A:C,3,0))<TODAY(), "VENCIDO – "&TEXT(SUM(Tabela1[[#This Row],[DATA_CURSO]],VLOOKUP(Tabela1[[#This Row],[DESCRICAO]],RENOVAÇÃO!A:C,3,0)),"dd/mm/aa"), "EM DIA – vence em "&TEXT(SUM(Tabela1[[#This Row],[DATA_CURSO]],VLOOKUP(Tabela1[[#This Row],[DESCRICAO]],RENOVAÇÃO!A:C,3,0)),"dd/mm/aa")), "NÃO É NECESSÁRIO RENOVAR"))) -> VENCIDO – 08/04/25 | Y14: =IF(Tabela1[[#This Row],[FILIAL]]=1,"SINOP",IF(Tabela1[[#This Row],[FILIAL]]=2,"DOURADOS",IF(Tabela1[[#This Row],[FILIAL]]=3,"NOVA MUTUM",IF(Tabela1[[#This Row],[FILIAL]]=4,"FULLING",IF(Tabela1[[#This Row],[FILIAL]]=5,"SÃO PAULO",IF(Tabela1[[#This Row],[FILIAL]]=6,"SIDROLÂNDIA",IF(Tabela1[[#This Row],[FILIAL]]=8,"BALSAS",IF(Tabela1[[#This Row],[FILIAL]]=10,"LUIS EDUARDO MAGALHÃES","")))))))) -> LUIS EDUARDO MAGALHÃES | Z14: =VLOOKUP(N14,RENOVAÇÃO!A:D,4,0) -> TRILHA SEGURANÇA DO TRABALHO | AA14: =CONCATENATE("• ", Tabela1[[#This Row],[DESCRICAO]], " - ",Tabela1[[#This Row],[STATUS_GERAL]]) -> • NR 20 - SEG. E TRAB. INFLAMÁVEIS E COMBUSTIVEIS CLASSE III - AVANÇADO - VENCIDO – 08/04/25
A15: 3 | B15: GABRIEL JOSE FRANCISCO SANTOS | C15: 43683 | D15: NORMAL | E15: 5 | F15: GABRIEL DA SILVA OLIVEIRA BROCHADO | G15: 801 - 06:00 AS 18:00 4-3 E 3-4 A1 | H15: EXPORTAÇÃO | I15: 134 | J15: 5076 | K15: OPERADOR MAQUINAS AUTOPROPELIDAS | L15: 235 | M15: CURSO | N15: NR 35 - TRABALHO EM ALTURA | P15: Concluido | Q15: 1 | R15: 1 | S15: 102 | T15: PROCESSO INDUSTRIAL | U15: 45827 | V15: BIENAL | W15: -603 | X15: =IF(Tabela1[[#This Row],[DATA_CURSO]]="", "PENDENTE", IF(Tabela1[[#This Row],[TIPO_RENOVACAO]]="QUANDO NECESSARIO", "EM DIA – não é necessário renovar", IFERROR( IF(SUM(Tabela1[[#This Row],[DATA_CURSO]],VLOOKUP(Tabela1[[#This Row],[DESCRICAO]],RENOVAÇÃO!A:C,3,0))<TODAY(), "VENCIDO – "&TEXT(SUM(Tabela1[[#This Row],[DATA_CURSO]],VLOOKUP(Tabela1[[#This Row],[DESCRICAO]],RENOVAÇÃO!A:C,3,0)),"dd/mm/aa"), "EM DIA – vence em "&TEXT(SUM(Tabela1[[#This Row],[DATA_CURSO]],VLOOKUP(Tabela1[[#This Row],[DESCRICAO]],RENOVAÇÃO!A:C,3,0)),"dd/mm/aa")), "NÃO É NECESSÁRIO RENOVAR"))) -> EM DIA – vence em 19/06/27 | Y15: =IF(Tabela1[[#This Row],[FILIAL]]=1,"SINOP",IF(Tabela1[[#This Row],[FILIAL]]=2,"DOURADOS",IF(Tabela1[[#This Row],[FILIAL]]=3,"NOVA MUTUM",IF(Tabela1[[#This Row],[FILIAL]]=4,"FULLING",IF(Tabela1[[#This Row],[FILIAL]]=5,"SÃO PAULO",IF(Tabela1[[#This Row],[FILIAL]]=6,"SIDROLÂNDIA",IF(Tabela1[[#This Row],[FILIAL]]=8,"BALSAS",IF(Tabela1[[#This Row],[FILIAL]]=10,"LUIS EDUARDO MAGALHÃES","")))))))) -> SINOP | Z15: =VLOOKUP(N15,RENOVAÇÃO!A:D,4,0) -> TRILHA SEGURANÇA DO TRABALHO | AA15: =CONCATENATE("• ", Tabela1[[#This Row],[DESCRICAO]], " - ",Tabela1[[#This Row],[STATUS_GERAL]]) -> • NR 35 - TRABALHO EM ALTURA - EM DIA – vence em 19/06/27
A16: 3 | B16: GABRIEL JOSE FRANCISCO SANTOS | C16: 43683 | D16: NORMAL | E16: 5 | F16: GABRIEL DA SILVA OLIVEIRA BROCHADO | G16: 801 - 06:00 AS 18:00 4-3 E 3-4 A1 | H16: EXPORTAÇÃO | I16: 134 | J16: 5076 | K16: OPERADOR MAQUINAS AUTOPROPELIDAS | L16: 323 | M16: CURSO | N16: NR 26 - SINALIZAÇÃO DE SEGURANÇA | P16: Concluido | Q16: 1 | R16: 1 | S16: 102 | T16: PROCESSO INDUSTRIAL | U16: 45489 | V16: QUANDO NECESSARIO | X16: =IF(Tabela1[[#This Row],[DATA_CURSO]]="", "PENDENTE", IF(Tabela1[[#This Row],[TIPO_RENOVACAO]]="QUANDO NECESSARIO", "EM DIA – não é necessário renovar", IFERROR( IF(SUM(Tabela1[[#This Row],[DATA_CURSO]],VLOOKUP(Tabela1[[#This Row],[DESCRICAO]],RENOVAÇÃO!A:C,3,0))<TODAY(), "VENCIDO – "&TEXT(SUM(Tabela1[[#This Row],[DATA_CURSO]],VLOOKUP(Tabela1[[#This Row],[DESCRICAO]],RENOVAÇÃO!A:C,3,0)),"dd/mm/aa"), "EM DIA – vence em "&TEXT(SUM(Tabela1[[#This Row],[DATA_CURSO]],VLOOKUP(Tabela1[[#This Row],[DESCRICAO]],RENOVAÇÃO!A:C,3,0)),"dd/mm/aa")), "NÃO É NECESSÁRIO RENOVAR"))) -> EM DIA – não é necessário renovar | Y16: =IF(Tabela1[[#This Row],[FILIAL]]=1,"SINOP",IF(Tabela1[[#This Row],[FILIAL]]=2,"DOURADOS",IF(Tabela1[[#This Row],[FILIAL]]=3,"NOVA MUTUM",IF(Tabela1[[#This Row],[FILIAL]]=4,"FULLING",IF(Tabela1[[#This Row],[FILIAL]]=5,"SÃO PAULO",IF(Tabela1[[#This Row],[FILIAL]]=6,"SIDROLÂNDIA",IF(Tabela1[[#This Row],[FILIAL]]=8,"BALSAS",IF(Tabela1[[#This Row],[FILIAL]]=10,"LUIS EDUARDO MAGALHÃES","")))))))) -> SINOP | Z16: =VLOOKUP(N16,RENOVAÇÃO!A:D,4,0) -> TRILHA SEGURANÇA DO TRABALHO | AA16: =CONCATENATE("• ", Tabela1[[#This Row],[DESCRICAO]], " - ",Tabela1[[#This Row],[STATUS_GERAL]]) -> • NR 26 - SINALIZAÇÃO DE SEGURANÇA - EM DIA – não é necessário renovar
A17: 3 | B17: GABRIEL JOSE FRANCISCO SANTOS | C17: 43683 | D17: NORMAL | E17: 5 | F17: GABRIEL DA SILVA OLIVEIRA BROCHADO | G17: 801 - 06:00 AS 18:00 4-3 E 3-4 A1 | H17: EXPORTAÇÃO | I17: 134 | J17: 5076 | K17: OPERADOR MAQUINAS AUTOPROPELIDAS | L17: 200 | M17: CURSO | N17: NR 33 - SEGURANÇA E SAUDE NOS TRABALHOS EM ESPAÇOS CONFINADOS - VIGIA E TRABALHADOR | P17: Concluido | Q17: 1 | R17: 3 | S17: 114 | T17: OPERAÇÕES | U17: 45911 | V17: ANUAL | W17: -322 | X17: =IF(Tabela1[[#This Row],[DATA_CURSO]]="", "PENDENTE", IF(Tabela1[[#This Row],[TIPO_RENOVACAO]]="QUANDO NECESSARIO", "EM DIA – não é necessário renovar", IFERROR( IF(SUM(Tabela1[[#This Row],[DATA_CURSO]],VLOOKUP(Tabela1[[#This Row],[DESCRICAO]],RENOVAÇÃO!A:C,3,0))<TODAY(), "VENCIDO – "&TEXT(SUM(Tabela1[[#This Row],[DATA_CURSO]],VLOOKUP(Tabela1[[#This Row],[DESCRICAO]],RENOVAÇÃO!A:C,3,0)),"dd/mm/aa"), "EM DIA – vence em "&TEXT(SUM(Tabela1[[#This Row],[DATA_CURSO]],VLOOKUP(Tabela1[[#This Row],[DESCRICAO]],RENOVAÇÃO!A:C,3,0)),"dd/mm/aa")), "NÃO É NECESSÁRIO RENOVAR"))) -> EM DIA – vence em 11/09/26 | Y17: =IF(Tabela1[[#This Row],[FILIAL]]=1,"SINOP",IF(Tabela1[[#This Row],[FILIAL]]=2,"DOURADOS",IF(Tabela1[[#This Row],[FILIAL]]=3,"NOVA MUTUM",IF(Tabela1[[#This Row],[FILIAL]]=4,"FULLING",IF(Tabela1[[#This Row],[FILIAL]]=5,"SÃO PAULO",IF(Tabela1[[#This Row],[FILIAL]]=6,"SIDROLÂNDIA",IF(Tabela1[[#This Row],[FILIAL]]=8,"BALSAS",IF(Tabela1[[#This Row],[FILIAL]]=10,"LUIS EDUARDO MAGALHÃES","")))))))) -> NOVA MUTUM | Z17: =VLOOKUP(N17,RENOVAÇÃO!A:D,4,0) -> TRILHA SEGURANÇA DO TRABALHO | AA17: =CONCATENATE("• ", Tabela1[[#This Row],[DESCRICAO]], " - ",Tabela1[[#This Row],[STATUS_GERAL]]) -> • NR 33 - SEGURANÇA E SAUDE NOS TRABALHOS EM ESPAÇOS CONFINADOS - VIGIA E TRABALHADOR - EM DIA – vence em 11/09/26
A18: 3 | B18: GABRIEL JOSE FRANCISCO SANTOS | C18: 43683 | D18: NORMAL | E18: 5 | F18: GABRIEL DA SILVA OLIVEIRA BROCHADO | G18: 801 - 06:00 AS 18:00 4-3 E 3-4 A1 | H18: EXPORTAÇÃO | I18: 134 | J18: 5076 | K18: OPERADOR MAQUINAS AUTOPROPELIDAS | L18: 320 | M18: CURSO | N18: NR 11 - OPERAÇÃO DE TALHAS E PONTE ROLANTE | P18: Concluido | Q18: 1 | R18: 1 | S18: 80 | T18: MANUTENÇÃO INDUSTRIAL | U18: 44887 | V18: BIENAL | W18: 337 | X18: =IF(Tabela1[[#This Row],[DATA_CURSO]]="", "PENDENTE", IF(Tabela1[[#This Row],[TIPO_RENOVACAO]]="QUANDO NECESSARIO", "EM DIA – não é necessário renovar", IFERROR( IF(SUM(Tabela1[[#This Row],[DATA_CURSO]],VLOOKUP(Tabela1[[#This Row],[DESCRICAO]],RENOVAÇÃO!A:C,3,0))<TODAY(), "VENCIDO – "&TEXT(SUM(Tabela1[[#This Row],[DATA_CURSO]],VLOOKUP(Tabela1[[#This Row],[DESCRICAO]],RENOVAÇÃO!A:C,3,0)),"dd/mm/aa"), "EM DIA – vence em "&TEXT(SUM(Tabela1[[#This Row],[DATA_CURSO]],VLOOKUP(Tabela1[[#This Row],[DESCRICAO]],RENOVAÇÃO!A:C,3,0)),"dd/mm/aa")), "NÃO É NECESSÁRIO RENOVAR"))) -> VENCIDO – 21/11/24 | Y18: =IF(Tabela1[[#This Row],[FILIAL]]=1,"SINOP",IF(Tabela1[[#This Row],[FILIAL]]=2,"DOURADOS",IF(Tabela1[[#This Row],[FILIAL]]=3,"NOVA MUTUM",IF(Tabela1[[#This Row],[FILIAL]]=4,"FULLING",IF(Tabela1[[#This Row],[FILIAL]]=5,"SÃO PAULO",IF(Tabela1[[#This Row],[FILIAL]]=6,"SIDROLÂNDIA",IF(Tabela1[[#This Row],[FILIAL]]=8,"BALSAS",IF(Tabela1[[#This Row],[FILIAL]]=10,"LUIS EDUARDO MAGALHÃES","")))))))) -> SINOP | Z18: =VLOOKUP(N18,RENOVAÇÃO!A:D,4,0) -> TRILHA SEGURANÇA DO TRABALHO | AA18: =CONCATENATE("• ", Tabela1[[#This Row],[DESCRICAO]], " - ",Tabela1[[#This Row],[STATUS_GERAL]]) -> • NR 11 - OPERAÇÃO DE TALHAS E PONTE ROLANTE - VENCIDO – 21/11/24
A19: 3 | B19: GABRIEL JOSE FRANCISCO SANTOS | C19: 43683 | D19: NORMAL | E19: 5 | F19: GABRIEL DA SILVA OLIVEIRA BROCHADO | G19: 801 - 06:00 AS 18:00 4-3 E 3-4 A1 | H19: EXPORTAÇÃO | I19: 134 | J19: 5076 | K19: OPERADOR MAQUINAS AUTOPROPELIDAS | L19: 129 | M19: CURSO | N19: NR 13 - SEGURANÇA NA OPERAÇÃO VASOS DE PRESSÃO | P19: Concluido | Q19: 1 | R19: 1 | S19: 102 | T19: PROCESSO INDUSTRIAL | U19: 44608 | V19: QUANDO NECESSARIO | X19: =IF(Tabela1[[#This Row],[DATA_CURSO]]="", "PENDENTE", IF(Tabela1[[#This Row],[TIPO_RENOVACAO]]="QUANDO NECESSARIO", "EM DIA – não é necessário renovar", IFERROR( IF(SUM(Tabela1[[#This Row],[DATA_CURSO]],VLOOKUP(Tabela1[[#This Row],[DESCRICAO]],RENOVAÇÃO!A:C,3,0))<TODAY(), "VENCIDO – "&TEXT(SUM(Tabela1[[#This Row],[DATA_CURSO]],VLOOKUP(Tabela1[[#This Row],[DESCRICAO]],RENOVAÇÃO!A:C,3,0)),"dd/mm/aa"), "EM DIA – vence em "&TEXT(SUM(Tabela1[[#This Row],[DATA_CURSO]],VLOOKUP(Tabela1[[#This Row],[DESCRICAO]],RENOVAÇÃO!A:C,3,0)),"dd/mm/aa")), "NÃO É NECESSÁRIO RENOVAR"))) -> EM DIA – não é necessário renovar | Y19: =IF(Tabela1[[#This Row],[FILIAL]]=1,"SINOP",IF(Tabela1[[#This Row],[FILIAL]]=2,"DOURADOS",IF(Tabela1[[#This Row],[FILIAL]]=3,"NOVA MUTUM",IF(Tabela1[[#This Row],[FILIAL]]=4,"FULLING",IF(Tabela1[[#This Row],[FILIAL]]=5,"SÃO PAULO",IF(Tabela1[[#This Row],[FILIAL]]=6,"SIDROLÂNDIA",IF(Tabela1[[#This Row],[FILIAL]]=8,"BALSAS",IF(Tabela1[[#This Row],[FILIAL]]=10,"LUIS EDUARDO MAGALHÃES","")))))))) -> SINOP | Z19: =VLOOKUP(N19,RENOVAÇÃO!A:D,4,0) -> TRILHA SEGURANÇA DO TRABALHO | AA19: =CONCATENATE("• ", Tabela1[[#This Row],[DESCRICAO]], " - ",Tabela1[[#This Row],[STATUS_GERAL]]) -> • NR 13 - SEGURANÇA NA OPERAÇÃO VASOS DE PRESSÃO - EM DIA – não é necessário renovar
A20: 3 | B20: GABRIEL JOSE FRANCISCO SANTOS | C20: 43683 | D20: NORMAL | E20: 5 | F20: GABRIEL DA SILVA OLIVEIRA BROCHADO | G20: 801 - 06:00 AS 18:00 4-3 E 3-4 A1 | H20: EXPORTAÇÃO | I20: 134 | J20: 5076 | K20: OPERADOR MAQUINAS AUTOPROPELIDAS | L20: 322 | M20: CURSO | N20: NR 26 - SINALIZAÇÃO DE SEGURANÇA | P20: Concluido | Q20: 1 | R20: 1 | S20: 102 | T20: PROCESSO INDUSTRIAL | U20: 45489 | V20: QUANDO NECESSARIO | X20: =IF(Tabela1[[#This Row],[DATA_CURSO]]="", "PENDENTE", IF(Tabela1[[#This Row],[TIPO_RENOVACAO]]="QUANDO NECESSARIO", "EM DIA – não é necessário renovar", IFERROR( IF(SUM(Tabela1[[#This Row],[DATA_CURSO]],VLOOKUP(Tabela1[[#This Row],[DESCRICAO]],RENOVAÇÃO!A:C,3,0))<TODAY(), "VENCIDO – "&TEXT(SUM(Tabela1[[#This Row],[DATA_CURSO]],VLOOKUP(Tabela1[[#This Row],[DESCRICAO]],RENOVAÇÃO!A:C,3,0)),"dd/mm/aa"), "EM DIA – vence em "&TEXT(SUM(Tabela1[[#This Row],[DATA_CURSO]],VLOOKUP(Tabela1[[#This Row],[DESCRICAO]],RENOVAÇÃO!A:C,3,0)),"dd/mm/aa")), "NÃO É NECESSÁRIO RENOVAR"))) -> EM DIA – não é necessário renovar | Y20: =IF(Tabela1[[#This Row],[FILIAL]]=1,"SINOP",IF(Tabela1[[#This Row],[FILIAL]]=2,"DOURADOS",IF(Tabela1[[#This Row],[FILIAL]]=3,"NOVA MUTUM",IF(Tabela1[[#This Row],[FILIAL]]=4,"FULLING",IF(Tabela1[[#This Row],[FILIAL]]=5,"SÃO PAULO",IF(Tabela1[[#This Row],[FILIAL]]=6,"SIDROLÂNDIA",IF(Tabela1[[#This Row],[FILIAL]]=8,"BALSAS",IF(Tabela1[[#This Row],[FILIAL]]=10,"LUIS EDUARDO MAGALHÃES","")))))))) -> SINOP | Z20: =VLOOKUP(N20,RENOVAÇÃO!A:D,4,0) -> TRILHA SEGURANÇA DO TRABALHO | AA20: =CONCATENATE("• ", Tabela1[[#This Row],[DESCRICAO]], " - ",Tabela1[[#This Row],[STATUS_GERAL]]) -> • NR 26 - SINALIZAÇÃO DE SEGURANÇA - EM DIA – não é necessário renovar
A21: 3 | B21: GABRIEL JOSE FRANCISCO SANTOS | C21: 43683 | D21: NORMAL | E21: 5 | F21: GABRIEL DA SILVA OLIVEIRA BROCHADO | G21: 801 - 06:00 AS 18:00 4-3 E 3-4 A1 | H21: EXPORTAÇÃO | I21: 134 | J21: 5076 | K21: OPERADOR MAQUINAS AUTOPROPELIDAS | L21: 271 | M21: CURSO | N21: NR 20 - SEG. E TRAB. INFLAMÁVEIS E COMBUSTIVEIS CLASSE III - BASICO | P21: Concluido | Q21: 1 | R21: 3 | S21: 102 | T21: PROCESSO INDUSTRIAL | U21: 45502 | V21: TRIENAL | W21: -643 | X21: =IF(Tabela1[[#This Row],[DATA_CURSO]]="", "PENDENTE", IF(Tabela1[[#This Row],[TIPO_RENOVACAO]]="QUANDO NECESSARIO", "EM DIA – não é necessário renovar", IFERROR( IF(SUM(Tabela1[[#This Row],[DATA_CURSO]],VLOOKUP(Tabela1[[#This Row],[DESCRICAO]],RENOVAÇÃO!A:C,3,0))<TODAY(), "VENCIDO – "&TEXT(SUM(Tabela1[[#This Row],[DATA_CURSO]],VLOOKUP(Tabela1[[#This Row],[DESCRICAO]],RENOVAÇÃO!A:C,3,0)),"dd/mm/aa"), "EM DIA – vence em "&TEXT(SUM(Tabela1[[#This Row],[DATA_CURSO]],VLOOKUP(Tabela1[[#This Row],[DESCRICAO]],RENOVAÇÃO!A:C,3,0)),"dd/mm/aa")), "NÃO É NECESSÁRIO RENOVAR"))) -> EM DIA – vence em 29/07/27 | Y21: =IF(Tabela1[[#This Row],[FILIAL]]=1,"SINOP",IF(Tabela1[[#This Row],[FILIAL]]=2,"DOURADOS",IF(Tabela1[[#This Row],[FILIAL]]=3,"NOVA MUTUM",IF(Tabela1[[#This Row],[FILIAL]]=4,"FULLING",IF(Tabela1[[#This Row],[FILIAL]]=5,"SÃO PAULO",IF(Tabela1[[#This Row],[FILIAL]]=6,"SIDROLÂNDIA",IF(Tabela1[[#This Row],[FILIAL]]=8,"BALSAS",IF(Tabela1[[#This Row],[FILIAL]]=10,"LUIS EDUARDO MAGALHÃES","")))))))) -> NOVA MUTUM | Z21: =VLOOKUP(N21,RENOVAÇÃO!A:D,4,0) -> TRILHA SEGURANÇA DO TRABALHO | AA21: =CONCATENATE("• ", Tabela1[[#This Row],[DESCRICAO]], " - ",Tabela1[[#This Row],[STATUS_GERAL]]) -> • NR 20 - SEG. E TRAB. INFLAMÁVEIS E COMBUSTIVEIS CLASSE III - BASICO - EM DIA – vence em 29/07/27
A22: 3 | B22: GABRIEL JOSE FRANCISCO SANTOS | C22: 43683 | D22: NORMAL | E22: 5 | F22: GABRIEL DA SILVA OLIVEIRA BROCHADO | G22: 801 - 06:00 AS 18:00 4-3 E 3-4 A1 | H22: EXPORTAÇÃO | I22: 134 | J22: 5076 | K22: OPERADOR MAQUINAS AUTOPROPELIDAS | L22: 82 | M22: CURSO | N22: NR 10 - SEGURANÇA EM INSTALAÇÕES E SERVIÇOS EM ELETRICIDADE ( BASÍCO) | P22: Concluido | Q22: 1 | R22: 6 | S22: 80 | T22: MANUTENÇÃO INDUSTRIAL | U22: 45870 | V22: BIENAL | W22: -646 | X22: =IF(Tabela1[[#This Row],[DATA_CURSO]]="", "PENDENTE", IF(Tabela1[[#This Row],[TIPO_RENOVACAO]]="QUANDO NECESSARIO", "EM DIA – não é necessário renovar", IFERROR( IF(SUM(Tabela1[[#This Row],[DATA_CURSO]],VLOOKUP(Tabela1[[#This Row],[DESCRICAO]],RENOVAÇÃO!A:C,3,0))<TODAY(), "VENCIDO – "&TEXT(SUM(Tabela1[[#This Row],[DATA_CURSO]],VLOOKUP(Tabela1[[#This Row],[DESCRICAO]],RENOVAÇÃO!A:C,3,0)),"dd/mm/aa"), "EM DIA – vence em "&TEXT(SUM(Tabela1[[#This Row],[DATA_CURSO]],VLOOKUP(Tabela1[[#This Row],[DESCRICAO]],RENOVAÇÃO!A:C,3,0)),"dd/mm/aa")), "NÃO É NECESSÁRIO RENOVAR"))) -> EM DIA – vence em 01/08/27 | Y22: =IF(Tabela1[[#This Row],[FILIAL]]=1,"SINOP",IF(Tabela1[[#This Row],[FILIAL]]=2,"DOURADOS",IF(Tabela1[[#This Row],[FILIAL]]=3,"NOVA MUTUM",IF(Tabela1[[#This Row],[FILIAL]]=4,"FULLING",IF(Tabela1[[#This Row],[FILIAL]]=5,"SÃO PAULO",IF(Tabela1[[#This Row],[FILIAL]]=6,"SIDROLÂNDIA",IF(Tabela1[[#This Row],[FILIAL]]=8,"BALSAS",IF(Tabela1[[#This Row],[FILIAL]]=10,"LUIS EDUARDO MAGALHÃES","")))))))) -> SIDROLÂNDIA | Z22: =VLOOKUP(N22,RENOVAÇÃO!A:D,4,0) -> TRILHA SEGURANÇA DO TRABALHO | AA22: =CONCATENATE("• ", Tabela1[[#This Row],[DESCRICAO]], " - ",Tabela1[[#This Row],[STATUS_GERAL]]) -> • NR 10 - SEGURANÇA EM INSTALAÇÕES E SERVIÇOS EM ELETRICIDADE ( BASÍCO) - EM DIA – vence em 01/08/27
A23: 3 | B23: GABRIEL JOSE FRANCISCO SANTOS | C23: 43683 | D23: NORMAL | E23: 5 | F23: GABRIEL DA SILVA OLIVEIRA BROCHADO | G23: 801 - 06:00 AS 18:00 4-3 E 3-4 A1 | H23: EXPORTAÇÃO | I23: 134 | J23: 5076 | K23: OPERADOR MAQUINAS AUTOPROPELIDAS | L23: 104 | M23: CURSO | N23: BLOQUEIO E SINALIZAÇÃO DE ENERGIAS PERIGOSAS - LOCKOUT/TAGOUT - NR10 E NR12 | P23: Concluido | Q23: 1 | R23: 1 | S23: 114 | T23: OPERAÇÕES | U23: 44582 | V23: QUANDO NECESSARIO | X23: =IF(Tabela1[[#This Row],[DATA_CURSO]]="", "PENDENTE", IF(Tabela1[[#This Row],[TIPO_RENOVACAO]]="QUANDO NECESSARIO", "EM DIA – não é necessário renovar", IFERROR( IF(SUM(Tabela1[[#This Row],[DATA_CURSO]],VLOOKUP(Tabela1[[#This Row],[DESCRICAO]],RENOVAÇÃO!A:C,3,0))<TODAY(), "VENCIDO – "&TEXT(SUM(Tabela1[[#This Row],[DATA_CURSO]],VLOOKUP(Tabela1[[#This Row],[DESCRICAO]],RENOVAÇÃO!A:C,3,0)),"dd/mm/aa"), "EM DIA – vence em "&TEXT(SUM(Tabela1[[#This Row],[DATA_CURSO]],VLOOKUP(Tabela1[[#This Row],[DESCRICAO]],RENOVAÇÃO!A:C,3,0)),"dd/mm/aa")), "NÃO É NECESSÁRIO RENOVAR"))) -> EM DIA – não é necessário renovar | Y23: =IF(Tabela1[[#This Row],[FILIAL]]=1,"SINOP",IF(Tabela1[[#This Row],[FILIAL]]=2,"DOURADOS",IF(Tabela1[[#This Row],[FILIAL]]=3,"NOVA MUTUM",IF(Tabela1[[#This Row],[FILIAL]]=4,"FULLING",IF(Tabela1[[#This Row],[FILIAL]]=5,"SÃO PAULO",IF(Tabela1[[#This Row],[FILIAL]]=6,"SIDROLÂNDIA",IF(Tabela1[[#This Row],[FILIAL]]=8,"BALSAS",IF(Tabela1[[#This Row],[FILIAL]]=10,"LUIS EDUARDO MAGALHÃES","")))))))) -> SINOP | Z23: =VLOOKUP(N23,RENOVAÇÃO!A:D,4,0) -> TRILHA SEGURANÇA DO TRABALHO | AA23: =CONCATENATE("• ", Tabela1[[#This Row],[DESCRICAO]], " - ",Tabela1[[#This Row],[STATUS_GERAL]]) -> • BLOQUEIO E SINALIZAÇÃO DE ENERGIAS PERIGOSAS - LOCKOUT/TAGOUT - NR10 E NR12 - EM DIA – não é necessário renovar
A24: 3 | B24: GABRIEL JOSE FRANCISCO SANTOS | C24: 43683 | D24: NORMAL | E24: 5 | F24: GABRIEL DA SILVA OLIVEIRA BROCHADO | G24: 801 - 06:00 AS 18:00 4-3 E 3-4 A1 | H24: EXPORTAÇÃO | I24: 134 | J24: 5076 | K24: OPERADOR MAQUINAS AUTOPROPELIDAS | L24: 2 | M24: CURSO | N24: NR 35 - TRABALHO EM ALTURA | P24: Concluido | Q24: 1 | R24: 1 | S24: 102 | T24: PROCESSO INDUSTRIAL | U24: 45374 | V24: BIENAL | W24: -150 | X24: =IF(Tabela1[[#This Row],[DATA_CURSO]]="", "PENDENTE", IF(Tabela1[[#This Row],[TIPO_RENOVACAO]]="QUANDO NECESSARIO", "EM DIA – não é necessário renovar", IFERROR( IF(SUM(Tabela1[[#This Row],[DATA_CURSO]],VLOOKUP(Tabela1[[#This Row],[DESCRICAO]],RENOVAÇÃO!A:C,3,0))<TODAY(), "VENCIDO – "&TEXT(SUM(Tabela1[[#This Row],[DATA_CURSO]],VLOOKUP(Tabela1[[#This Row],[DESCRICAO]],RENOVAÇÃO!A:C,3,0)),"dd/mm/aa"), "EM DIA – vence em "&TEXT(SUM(Tabela1[[#This Row],[DATA_CURSO]],VLOOKUP(Tabela1[[#This Row],[DESCRICAO]],RENOVAÇÃO!A:C,3,0)),"dd/mm/aa")), "NÃO É NECESSÁRIO RENOVAR"))) -> EM DIA – vence em 23/03/26 | Y24: =IF(Tabela1[[#This Row],[FILIAL]]=1,"SINOP",IF(Tabela1[[#This Row],[FILIAL]]=2,"DOURADOS",IF(Tabela1[[#This Row],[FILIAL]]=3,"NOVA MUTUM",IF(Tabela1[[#This Row],[FILIAL]]=4,"FULLING",IF(Tabela1[[#This Row],[FILIAL]]=5,"SÃO PAULO",IF(Tabela1[[#This Row],[FILIAL]]=6,"SIDROLÂNDIA",IF(Tabela1[[#This Row],[FILIAL]]=8,"BALSAS",IF(Tabela1[[#This Row],[FILIAL]]=10,"LUIS EDUARDO MAGALHÃES","")))))))) -> SINOP | Z24: =VLOOKUP(N24,RENOVAÇÃO!A:D,4,0) -> TRILHA SEGURANÇA DO TRABALHO | AA24: =CONCATENATE("• ", Tabela1[[#This Row],[DESCRICAO]], " - ",Tabela1[[#This Row],[STATUS_GERAL]]) -> • NR 35 - TRABALHO EM ALTURA - EM DIA – vence em 23/03/26
A25: 1 | B25: GABRIEL DE OLIVEIRA | C25: 43570 | D25: NORMAL | E25: 5 | F25: GABRIEL DA SILVA OLIVEIRA BROCHADO | G25: 801 - 06:00 AS 18:00 4-3 E 3-4 A1 | H25: EXPORTAÇÃO | I25: 172 | J25: 5058 | K25: OPERADOR MAQUINAS AUTOPROPELIDAS | L25: 317 | M25: CURSO | N25: NR 35 - TRABALHO EM ALTURA | P25: Concluido | Q25: 1 | R25: 1 | S25: 114 | T25: OPERAÇÕES | U25: 45405 | V25: BIENAL | W25: -181 | X25: =IF(Tabela1[[#This Row],[DATA_CURSO]]="", "PENDENTE", IF(Tabela1[[#This Row],[TIPO_RENOVACAO]]="QUANDO NECESSARIO", "EM DIA – não é necessário renovar", IFERROR( IF(SUM(Tabela1[[#This Row],[DATA_CURSO]],VLOOKUP(Tabela1[[#This Row],[DESCRICAO]],RENOVAÇÃO!A:C,3,0))<TODAY(), "VENCIDO – "&TEXT(SUM(Tabela1[[#This Row],[DATA_CURSO]],VLOOKUP(Tabela1[[#This Row],[DESCRICAO]],RENOVAÇÃO!A:C,3,0)),"dd/mm/aa"), "EM DIA – vence em "&TEXT(SUM(Tabela1[[#This Row],[DATA_CURSO]],VLOOKUP(Tabela1[[#This Row],[DESCRICAO]],RENOVAÇÃO!A:C,3,0)),"dd/mm/aa")), "NÃO É NECESSÁRIO RENOVAR"))) -> EM DIA – vence em 23/04/26 | Y25: =IF(Tabela1[[#This Row],[FILIAL]]=1,"SINOP",IF(Tabela1[[#This Row],[FILIAL]]=2,"DOURADOS",IF(Tabela1[[#This Row],[FILIAL]]=3,"NOVA MUTUM",IF(Tabela1[[#This Row],[FILIAL]]=4,"FULLING",IF(Tabela1[[#This Row],[FILIAL]]=5,"SÃO PAULO",IF(Tabela1[[#This Row],[FILIAL]]=6,"SIDROLÂNDIA",IF(Tabela1[[#This Row],[FILIAL]]=8,"BALSAS",IF(Tabela1[[#This Row],[FILIAL]]=10,"LUIS EDUARDO MAGALHÃES","")))))))) -> SINOP | Z25: =VLOOKUP(N25,RENOVAÇÃO!A:D,4,0) -> TRILHA SEGURANÇA DO TRABALHO | AA25: =CONCATENATE("• ", Tabela1[[#This Row],[DESCRICAO]], " - ",Tabela1[[#This Row],[STATUS_GERAL]]) -> • NR 35 - TRABALHO EM ALTURA - EM DIA – vence em 23/04/26
A26: 1 | B26: GABRIEL DE OLIVEIRA | C26: 43570 | D26: NORMAL | E26: 5 | F26: GABRIEL DA SILVA OLIVEIRA BROCHADO | G26: 801 - 06:00 AS 18:00 4-3 E 3-4 A1 | H26: EXPORTAÇÃO | I26: 172 | J26: 5058 | K26: OPERADOR MAQUINAS AUTOPROPELIDAS | L26: 271 | M26: CURSO | N26: NR 20 - SEG. E TRAB. INFLAMÁVEIS E COMBUSTIVEIS CLASSE III - BASICO | P26: Concluido | Q26: 1 | R26: 1 | S26: 117 | T26: OBRAS CIVIS | U26: 45875 | V26: TRIENAL | W26: -1016 | X26: =IF(Tabela1[[#This Row],[DATA_CURSO]]="", "PENDENTE", IF(Tabela1[[#This Row],[TIPO_RENOVACAO]]="QUANDO NECESSARIO", "EM DIA – não é necessário renovar", IFERROR( IF(SUM(Tabela1[[#This Row],[DATA_CURSO]],VLOOKUP(Tabela1[[#This Row],[DESCRICAO]],RENOVAÇÃO!A:C,3,0))<TODAY(), "VENCIDO – "&TEXT(SUM(Tabela1[[#This Row],[DATA_CURSO]],VLOOKUP(Tabela1[[#This Row],[DESCRICAO]],RENOVAÇÃO!A:C,3,0)),"dd/mm/aa"), "EM DIA – vence em "&TEXT(SUM(Tabela1[[#This Row],[DATA_CURSO]],VLOOKUP(Tabela1[[#This Row],[DESCRICAO]],RENOVAÇÃO!A:C,3,0)),"dd/mm/aa")), "NÃO É NECESSÁRIO RENOVAR"))) -> EM DIA – vence em 05/08/28 | Y26: =IF(Tabela1[[#This Row],[FILIAL]]=1,"SINOP",IF(Tabela1[[#This Row],[FILIAL]]=2,"DOURADOS",IF(Tabela1[[#This Row],[FILIAL]]=3,"NOVA MUTUM",IF(Tabela1[[#This Row],[FILIAL]]=4,"FULLING",IF(Tabela1[[#This Row],[FILIAL]]=5,"SÃO PAULO",IF(Tabela1[[#This Row],[FILIAL]]=6,"SIDROLÂNDIA",IF(Tabela1[[#This Row],[FILIAL]]=8,"BALSAS",IF(Tabela1[[#This Row],[FILIAL]]=10,"LUIS EDUARDO MAGALHÃES","")))))))) -> SINOP | Z26: =VLOOKUP(N26,RENOVAÇÃO!A:D,4,0) -> TRILHA SEGURANÇA DO TRABALHO | AA26: =CONCATENATE("• ", Tabela1[[#This Row],[DESCRICAO]], " - ",Tabela1[[#This Row],[STATUS_GERAL]]) -> • NR 20 - SEG. E TRAB. INFLAMÁVEIS E COMBUSTIVEIS CLASSE III - BASICO - EM DIA – vence em 05/08/28
A27: 1 | B27: GABRIEL DE OLIVEIRA | C27: 43570 | D27: NORMAL | E27: 5 | F27: GABRIEL DA SILVA OLIVEIRA BROCHADO | G27: 801 - 06:00 AS 18:00 4-3 E 3-4 A1 | H27: EXPORTAÇÃO | I27: 172 | J27: 5058 | K27: OPERADOR MAQUINAS AUTOPROPELIDAS | L27: 200 | M27: CURSO | N27: BLOQUEIO E SINALIZAÇÃO DE ENERGIAS PERIGOSAS - LOCKOUT/TAGOUT - NR10 E NR12 | P27: Concluido | Q27: 1 | R27: 1 | S27: 102 | T27: PROCESSO INDUSTRIAL | U27: 44883 | V27: QUANDO NECESSARIO | X27: =IF(Tabela1[[#This Row],[DATA_CURSO]]="", "PENDENTE", IF(Tabela1[[#This Row],[TIPO_RENOVACAO]]="QUANDO NECESSARIO", "EM DIA – não é necessário renovar", IFERROR( IF(SUM(Tabela1[[#This Row],[DATA_CURSO]],VLOOKUP(Tabela1[[#This Row],[DESCRICAO]],RENOVAÇÃO!A:C,3,0))<TODAY(), "VENCIDO – "&TEXT(SUM(Tabela1[[#This Row],[DATA_CURSO]],VLOOKUP(Tabela1[[#This Row],[DESCRICAO]],RENOVAÇÃO!A:C,3,0)),"dd/mm/aa"), "EM DIA – vence em "&TEXT(SUM(Tabela1[[#This Row],[DATA_CURSO]],VLOOKUP(Tabela1[[#This Row],[DESCRICAO]],RENOVAÇÃO!A:C,3,0)),"dd/mm/aa")), "NÃO É NECESSÁRIO RENOVAR"))) -> EM DIA – não é necessário renovar | Y27: =IF(Tabela1[[#This Row],[FILIAL]]=1,"SINOP",IF(Tabela1[[#This Row],[FILIAL]]=2,"DOURADOS",IF(Tabela1[[#This Row],[FILIAL]]=3,"NOVA MUTUM",IF(Tabela1[[#This Row],[FILIAL]]=4,"FULLING",IF(Tabela1[[#This Row],[FILIAL]]=5,"SÃO PAULO",IF(Tabela1[[#This Row],[FILIAL]]=6,"SIDROLÂNDIA",IF(Tabela1[[#This Row],[FILIAL]]=8,"BALSAS",IF(Tabela1[[#This Row],[FILIAL]]=10,"LUIS EDUARDO MAGALHÃES","")))))))) -> SINOP | Z27: =VLOOKUP(N27,RENOVAÇÃO!A:D,4,0) -> TRILHA SEGURANÇA DO TRABALHO | AA27: =CONCATENATE("• ", Tabela1[[#This Row],[DESCRICAO]], " - ",Tabela1[[#This Row],[STATUS_GERAL]]) -> • BLOQUEIO E SINALIZAÇÃO DE ENERGIAS PERIGOSAS - LOCKOUT/TAGOUT - NR10 E NR12 - EM DIA – não é necessário renovar
A28: 1 | B28: GABRIEL DE OLIVEIRA | C28: 43570 | D28: NORMAL | E28: 5 | F28: GABRIEL DA SILVA OLIVEIRA BROCHADO | G28: 801 - 06:00 AS 18:00 4-3 E 3-4 A1 | H28: EXPORTAÇÃO | I28: 172 | J28: 5058 | K28: OPERADOR MAQUINAS AUTOPROPELIDAS | L28: 1 | M28: CURSO | N28: NR 35 - TRABALHO EM ALTURA | P28: Concluido | Q28: 1 | R28: 1 | S28: 80 | T28: MANUTENÇÃO INDUSTRIAL | U28: 45349 | V28: BIENAL | W28: -125 | X28: =IF(Tabela1[[#This Row],[DATA_CURSO]]="", "PENDENTE", IF(Tabela1[[#This Row],[TIPO_RENOVACAO]]="QUANDO NECESSARIO", "EM DIA – não é necessário renovar", IFERROR( IF(SUM(Tabela1[[#This Row],[DATA_CURSO]],VLOOKUP(Tabela1[[#This Row],[DESCRICAO]],RENOVAÇÃO!A:C,3,0))<TODAY(), "VENCIDO – "&TEXT(SUM(Tabela1[[#This Row],[DATA_CURSO]],VLOOKUP(Tabela1[[#This Row],[DESCRICAO]],RENOVAÇÃO!A:C,3,0)),"dd/mm/aa"), "EM DIA – vence em "&TEXT(SUM(Tabela1[[#This Row],[DATA_CURSO]],VLOOKUP(Tabela1[[#This Row],[DESCRICAO]],RENOVAÇÃO!A:C,3,0)),"dd/mm/aa")), "NÃO É NECESSÁRIO RENOVAR"))) -> EM DIA – vence em 26/02/26 | Y28: =IF(Tabela1[[#This Row],[FILIAL]]=1,"SINOP",IF(Tabela1[[#This Row],[FILIAL]]=2,"DOURADOS",IF(Tabela1[[#This Row],[FILIAL]]=3,"NOVA MUTUM",IF(Tabela1[[#This Row],[FILIAL]]=4,"FULLING",IF(Tabela1[[#This Row],[FILIAL]]=5,"SÃO PAULO",IF(Tabela1[[#This Row],[FILIAL]]=6,"SIDROLÂNDIA",IF(Tabela1[[#This Row],[FILIAL]]=8,"BALSAS",IF(Tabela1[[#This Row],[FILIAL]]=10,"LUIS EDUARDO MAGALHÃES","")))))))) -> SINOP | Z28: =VLOOKUP(N28,RENOVAÇÃO!A:D,4,0) -> TRILHA SEGURANÇA DO TRABALHO | AA28: =CONCATENATE("• ", Tabela1[[#This Row],[DESCRICAO]], " - ",Tabela1[[#This Row],[STATUS_GERAL]]) -> • NR 35 - TRABALHO EM ALTURA - EM DIA – vence em 26/02/26
A29: 1 | B29: GABRIEL DE OLIVEIRA | C29: 43570 | D29: NORMAL | E29: 5 | F29: GABRIEL DA SILVA OLIVEIRA BROCHADO | G29: 801 - 06:00 AS 18:00 4-3 E 3-4 A1 | H29: EXPORTAÇÃO | I29: 172 | J29: 5058 | K29: OPERADOR MAQUINAS AUTOPROPELIDAS | L29: 262 | M29: CURSO | N29: NR 35 - TRABALHO EM ALTURA | P29: Concluido | Q29: 1 | R29: 1 | S29: 114 | T29: OPERAÇÕES | U29: 45349 | V29: BIENAL | W29: -125 | X29: =IF(Tabela1[[#This Row],[DATA_CURSO]]="", "PENDENTE", IF(Tabela1[[#This Row],[TIPO_RENOVACAO]]="QUANDO NECESSARIO", "EM DIA – não é necessário renovar", IFERROR( IF(SUM(Tabela1[[#This Row],[DATA_CURSO]],VLOOKUP(Tabela1[[#This Row],[DESCRICAO]],RENOVAÇÃO!A:C,3,0))<TODAY(), "VENCIDO – "&TEXT(SUM(Tabela1[[#This Row],[DATA_CURSO]],VLOOKUP(Tabela1[[#This Row],[DESCRICAO]],RENOVAÇÃO!A:C,3,0)),"dd/mm/aa"), "EM DIA – vence em "&TEXT(SUM(Tabela1[[#This Row],[DATA_CURSO]],VLOOKUP(Tabela1[[#This Row],[DESCRICAO]],RENOVAÇÃO!A:C,3,0)),"dd/mm/aa")), "NÃO É NECESSÁRIO RENOVAR"))) -> EM DIA – vence em 26/02/26 | Y29: =IF(Tabela1[[#This Row],[FILIAL]]=1,"SINOP",IF(Tabela1[[#This Row],[FILIAL]]=2,"DOURADOS",IF(Tabela1[[#This Row],[FILIAL]]=3,"NOVA MUTUM",IF(Tabela1[[#This Row],[FILIAL]]=4,"FULLING",IF(Tabela1[[#This Row],[FILIAL]]=5,"SÃO PAULO",IF(Tabela1[[#This Row],[FILIAL]]=6,"SIDROLÂNDIA",IF(Tabela1[[#This Row],[FILIAL]]=8,"BALSAS",IF(Tabela1[[#This Row],[FILIAL]]=10,"LUIS EDUARDO MAGALHÃES","")))))))) -> SINOP | Z29: =VLOOKUP(N29,RENOVAÇÃO!A:D,4,0) -> TRILHA SEGURANÇA DO TRABALHO | AA29: =CONCATENATE("• ", Tabela1[[#This Row],[DESCRICAO]], " - ",Tabela1[[#This Row],[STATUS_GERAL]]) -> • NR 35 - TRABALHO EM ALTURA - EM DIA – vence em 26/02/26
A30: 1 | B30: GABRIEL DE OLIVEIRA | C30: 43570 | D30: NORMAL | E30: 5 | F30: GABRIEL DA SILVA OLIVEIRA BROCHADO | G30: 801 - 06:00 AS 18:00 4-3 E 3-4 A1 | H30: EXPORTAÇÃO | I30: 172 | J30: 5058 | K30: OPERADOR MAQUINAS AUTOPROPELIDAS | L30: 28 | M30: CURSO | N30: NR 13 - SEGURANÇA NA OPERAÇÃO DE CALDEIRAS | P30: Concluido | Q30: 1 | R30: 1 | S30: 102 | T30: PROCESSO INDUSTRIAL | U30: 45042 | V30: QUANDO NECESSARIO | X30: =IF(Tabela1[[#This Row],[DATA_CURSO]]="", "PENDENTE", IF(Tabela1[[#This Row],[TIPO_RENOVACAO]]="QUANDO NECESSARIO", "EM DIA – não é necessário renovar", IFERROR( IF(SUM(Tabela1[[#This Row],[DATA_CURSO]],VLOOKUP(Tabela1[[#This Row],[DESCRICAO]],RENOVAÇÃO!A:C,3,0))<TODAY(), "VENCIDO – "&TEXT(SUM(Tabela1[[#This Row],[DATA_CURSO]],VLOOKUP(Tabela1[[#This Row],[DESCRICAO]],RENOVAÇÃO!A:C,3,0)),"dd/mm/aa"), "EM DIA – vence em "&TEXT(SUM(Tabela1[[#This Row],[DATA_CURSO]],VLOOKUP(Tabela1[[#This Row],[DESCRICAO]],RENOVAÇÃO!A:C,3,0)),"dd/mm/aa")), "NÃO É NECESSÁRIO RENOVAR"))) -> EM DIA – não é necessário renovar | Y30: =IF(Tabela1[[#This Row],[FILIAL]]=1,"SINOP",IF(Tabela1[[#This Row],[FILIAL]]=2,"DOURADOS",IF(Tabela1[[#This Row],[FILIAL]]=3,"NOVA MUTUM",IF(Tabela1[[#This Row],[FILIAL]]=4,"FULLING",IF(Tabela1[[#This Row],[FILIAL]]=5,"SÃO PAULO",IF(Tabela1[[#This Row],[FILIAL]]=6,"SIDROLÂNDIA",IF(Tabela1[[#This Row],[FILIAL]]=8,"BALSAS",IF(Tabela1[[#This Row],[FILIAL]]=10,"LUIS EDUARDO MAGALHÃES","")))))))) -> SINOP | Z30: =VLOOKUP(N30,RENOVAÇÃO!A:D,4,0) -> TRILHA SEGURANÇA DO TRABALHO | AA30: =CONCATENATE("• ", Tabela1[[#This Row],[DESCRICAO]], " - ",Tabela1[[#This Row],[STATUS_GERAL]]) -> • NR 13 - SEGURANÇA NA OPERAÇÃO DE CALDEIRAS - EM DIA – não é necessário renovar
A31: 1 | B31: GABRIEL DE OLIVEIRA | C31: 43570 | D31: NORMAL | E31: 5 | F31: GABRIEL DA SILVA OLIVEIRA BROCHADO | G31: 801 - 06:00 AS 18:00 4-3 E 3-4 A1 | H31: EXPORTAÇÃO | I31: 172 | J31: 5058 | K31: OPERADOR MAQUINAS AUTOPROPELIDAS | L31: 11 | M31: CURSO | N31: BLOQUEIO E SINALIZAÇÃO DE ENERGIAS PERIGOSAS - LOCKOUT/TAGOUT - NR10 E NR12 | P31: Concluido | Q31: 1 | R31: 1 | S31: 102 | T31: PROCESSO INDUSTRIAL | U31: 45125 | V31: QUANDO NECESSARIO | X31: =IF(Tabela1[[#This Row],[DATA_CURSO]]="", "PENDENTE", IF(Tabela1[[#This Row],[TIPO_RENOVACAO]]="QUANDO NECESSARIO", "EM DIA – não é necessário renovar", IFERROR( IF(SUM(Tabela1[[#This Row],[DATA_CURSO]],VLOOKUP(Tabela1[[#This Row],[DESCRICAO]],RENOVAÇÃO!A:C,3,0))<TODAY(), "VENCIDO – "&TEXT(SUM(Tabela1[[#This Row],[DATA_CURSO]],VLOOKUP(Tabela1[[#This Row],[DESCRICAO]],RENOVAÇÃO!A:C,3,0)),"dd/mm/aa"), "EM DIA – vence em "&TEXT(SUM(Tabela1[[#This Row],[DATA_CURSO]],VLOOKUP(Tabela1[[#This Row],[DESCRICAO]],RENOVAÇÃO!A:C,3,0)),"dd/mm/aa")), "NÃO É NECESSÁRIO RENOVAR"))) -> EM DIA – não é necessário renovar | Y31: =IF(Tabela1[[#This Row],[FILIAL]]=1,"SINOP",IF(Tabela1[[#This Row],[FILIAL]]=2,"DOURADOS",IF(Tabela1[[#This Row],[FILIAL]]=3,"NOVA MUTUM",IF(Tabela1[[#This Row],[FILIAL]]=4,"FULLING",IF(Tabela1[[#This Row],[FILIAL]]=5,"SÃO PAULO",IF(Tabela1[[#This Row],[FILIAL]]=6,"SIDROLÂNDIA",IF(Tabela1[[#This Row],[FILIAL]]=8,"BALSAS",IF(Tabela1[[#This Row],[FILIAL]]=10,"LUIS EDUARDO MAGALHÃES","")))))))) -> SINOP | Z31: =VLOOKUP(N31,RENOVAÇÃO!A:D,4,0) -> TRILHA SEGURANÇA DO TRABALHO | AA31: =CONCATENATE("• ", Tabela1[[#This Row],[DESCRICAO]], " - ",Tabela1[[#This Row],[STATUS_GERAL]]) -> • BLOQUEIO E SINALIZAÇÃO DE ENERGIAS PERIGOSAS - LOCKOUT/TAGOUT - NR10 E NR12 - EM DIA – não é necessário renovar
A32: 1 | B32: GABRIEL DE OLIVEIRA | C32: 43570 | D32: NORMAL | E32: 5 | F32: GABRIEL DA SILVA OLIVEIRA BROCHADO | G32: 801 - 06:00 AS 18:00 4-3 E 3-4 A1 | H32: EXPORTAÇÃO | I32: 172 | J32: 5058 | K32: OPERADOR MAQUINAS AUTOPROPELIDAS | L32: 26 | M32: CURSO | N32: NR 10 - SEGURANÇA EM INSTALAÇÕES E SERVIÇOS EM ELETRICIDADE ( BASÍCO) | P32: Concluido | Q32: 1 | R32: 2 | S32: 80 | T32: MANUTENÇÃO INDUSTRIAL | U32: 45401 | V32: BIENAL | W32: -177 | X32: =IF(Tabela1[[#This Row],[DATA_CURSO]]="", "PENDENTE", IF(Tabela1[[#This Row],[TIPO_RENOVACAO]]="QUANDO NECESSARIO", "EM DIA – não é necessário renovar", IFERROR( IF(SUM(Tabela1[[#This Row],[DATA_CURSO]],VLOOKUP(Tabela1[[#This Row],[DESCRICAO]],RENOVAÇÃO!A:C,3,0))<TODAY(), "VENCIDO – "&TEXT(SUM(Tabela1[[#This Row],[DATA_CURSO]],VLOOKUP(Tabela1[[#This Row],[DESCRICAO]],RENOVAÇÃO!A:C,3,0)),"dd/mm/aa"), "EM DIA – vence em "&TEXT(SUM(Tabela1[[#This Row],[DATA_CURSO]],VLOOKUP(Tabela1[[#This Row],[DESCRICAO]],RENOVAÇÃO!A:C,3,0)),"dd/mm/aa")), "NÃO É NECESSÁRIO RENOVAR"))) -> EM DIA – vence em 19/04/26 | Y32: =IF(Tabela1[[#This Row],[FILIAL]]=1,"SINOP",IF(Tabela1[[#This Row],[FILIAL]]=2,"DOURADOS",IF(Tabela1[[#This Row],[FILIAL]]=3,"NOVA MUTUM",IF(Tabela1[[#This Row],[FILIAL]]=4,"FULLING",IF(Tabela1[[#This Row],[FILIAL]]=5,"SÃO PAULO",IF(Tabela1[[#This Row],[FILIAL]]=6,"SIDROLÂNDIA",IF(Tabela1[[#This Row],[FILIAL]]=8,"BALSAS",IF(Tabela1[[#This Row],[FILIAL]]=10,"LUIS EDUARDO MAGALHÃES","")))))))) -> DOURADOS | Z32: =VLOOKUP(N32,RENOVAÇÃO!A:D,4,0) -> TRILHA SEGURANÇA DO TRABALHO | AA32: =CONCATENATE("• ", Tabela1[[#This Row],[DESCRICAO]], " - ",Tabela1[[#This Row],[STATUS_GERAL]]) -> • NR 10 - SEGURANÇA EM INSTALAÇÕES E SERVIÇOS EM ELETRICIDADE ( BASÍCO) - EM DIA – vence em 19/04/26
A33: 1 | B33: GABRIEL DE OLIVEIRA | C33: 43570 | D33: NORMAL | E33: 5 | F33: GABRIEL DA SILVA OLIVEIRA BROCHADO | G33: 801 - 06:00 AS 18:00 4-3 E 3-4 A1 | H33: EXPORTAÇÃO | I33: 172 | J33: 5058 | K33: OPERADOR MAQUINAS AUTOPROPELIDAS | L33: 8 | M33: CURSO | N33: DIREÇÃO DEFENSIVA - TEÓRICO | P33: Concluido | Q33: 1 | R33: 3 | S33: 113 | T33: FROTA | U33: 44568 | V33: QUANDO NECESSARIO | X33: =IF(Tabela1[[#This Row],[DATA_CURSO]]="", "PENDENTE", IF(Tabela1[[#This Row],[TIPO_RENOVACAO]]="QUANDO NECESSARIO", "EM DIA – não é necessário renovar", IFERROR( IF(SUM(Tabela1[[#This Row],[DATA_CURSO]],VLOOKUP(Tabela1[[#This Row],[DESCRICAO]],RENOVAÇÃO!A:C,3,0))<TODAY(), "VENCIDO – "&TEXT(SUM(Tabela1[[#This Row],[DATA_CURSO]],VLOOKUP(Tabela1[[#This Row],[DESCRICAO]],RENOVAÇÃO!A:C,3,0)),"dd/mm/aa"), "EM DIA – vence em "&TEXT(SUM(Tabela1[[#This Row],[DATA_CURSO]],VLOOKUP(Tabela1[[#This Row],[DESCRICAO]],RENOVAÇÃO!A:C,3,0)),"dd/mm/aa")), "NÃO É NECESSÁRIO RENOVAR"))) -> EM DIA – não é necessário renovar | Y33: =IF(Tabela1[[#This Row],[FILIAL]]=1,"SINOP",IF(Tabela1[[#This Row],[FILIAL]]=2,"DOURADOS",IF(Tabela1[[#This Row],[FILIAL]]=3,"NOVA MUTUM",IF(Tabela1[[#This Row],[FILIAL]]=4,"FULLING",IF(Tabela1[[#This Row],[FILIAL]]=5,"SÃO PAULO",IF(Tabela1[[#This Row],[FILIAL]]=6,"SIDROLÂNDIA",IF(Tabela1[[#This Row],[FILIAL]]=8,"BALSAS",IF(Tabela1[[#This Row],[FILIAL]]=10,"LUIS EDUARDO MAGALHÃES","")))))))) -> NOVA MUTUM | Z33: =VLOOKUP(N33,RENOVAÇÃO!A:D,4,0) -> TRILHA SEGURANÇA DO TRABALHO | AA33: =CONCATENATE("• ", Tabela1[[#This Row],[DESCRICAO]], " - ",Tabela1[[#This Row],[STATUS_GERAL]]) -> • DIREÇÃO DEFENSIVA - TEÓRICO - EM DIA – não é necessário renovar
A34: 1 | B34: GABRIEL DE OLIVEIRA | C34: 43570 | D34: NORMAL | E34: 5 | F34: GABRIEL DA SILVA OLIVEIRA BROCHADO | G34: 801 - 06:00 AS 18:00 4-3 E 3-4 A1 | H34: EXPORTAÇÃO | I34: 172 | J34: 5058 | K34: OPERADOR MAQUINAS AUTOPROPELIDAS | L34: 129 | M34: CURSO | N34: NR 20 - SEG. E TRAB. INFLAMÁVEIS E COMBUSTIVEIS CLASSE III - BASICO | P34: Concluido | Q34: 1 | R34: 1 | S34: 114 | T34: OPERAÇÕES | U34: 45945 | V34: TRIENAL | W34: -1086 | X34: =IF(Tabela1[[#This Row],[DATA_CURSO]]="", "PENDENTE", IF(Tabela1[[#This Row],[TIPO_RENOVACAO]]="QUANDO NECESSARIO", "EM DIA – não é necessário renovar", IFERROR( IF(SUM(Tabela1[[#This Row],[DATA_CURSO]],VLOOKUP(Tabela1[[#This Row],[DESCRICAO]],RENOVAÇÃO!A:C,3,0))<TODAY(), "VENCIDO – "&TEXT(SUM(Tabela1[[#This Row],[DATA_CURSO]],VLOOKUP(Tabela1[[#This Row],[DESCRICAO]],RENOVAÇÃO!A:C,3,0)),"dd/mm/aa"), "EM DIA – vence em "&TEXT(SUM(Tabela1[[#This Row],[DATA_CURSO]],VLOOKUP(Tabela1[[#This Row],[DESCRICAO]],RENOVAÇÃO!A:C,3,0)),"dd/mm/aa")), "NÃO É NECESSÁRIO RENOVAR"))) -> EM DIA – vence em 14/10/28 | Y34: =IF(Tabela1[[#This Row],[FILIAL]]=1,"SINOP",IF(Tabela1[[#This Row],[FILIAL]]=2,"DOURADOS",IF(Tabela1[[#This Row],[FILIAL]]=3,"NOVA MUTUM",IF(Tabela1[[#This Row],[FILIAL]]=4,"FULLING",IF(Tabela1[[#This Row],[FILIAL]]=5,"SÃO PAULO",IF(Tabela1[[#This Row],[FILIAL]]=6,"SIDROLÂNDIA",IF(Tabela1[[#This Row],[FILIAL]]=8,"BALSAS",IF(Tabela1[[#This Row],[FILIAL]]=10,"LUIS EDUARDO MAGALHÃES","")))))))) -> SINOP | Z34: =VLOOKUP(N34,RENOVAÇÃO!A:D,4,0) -> TRILHA SEGURANÇA DO TRABALHO | AA34: =CONCATENATE("• ", Tabela1[[#This Row],[DESCRICAO]], " - ",Tabela1[[#This Row],[STATUS_GERAL]]) -> • NR 20 - SEG. E TRAB. INFLAMÁVEIS E COMBUSTIVEIS CLASSE III - BASICO - EM DIA – vence em 14/10/28
A35: 1 | B35: GABRIEL DE OLIVEIRA | C35: 43570 | D35: NORMAL | E35: 5 | F35: GABRIEL DA SILVA OLIVEIRA BROCHADO | G35: 801 - 06:00 AS 18:00 4-3 E 3-4 A1 | H35: EXPORTAÇÃO | I35: 172 | J35: 5058 | K35: OPERADOR MAQUINAS AUTOPROPELIDAS | L35: 300 | M35: CURSO | N35: NR 26 - SINALIZAÇÃO DE SEGURANÇA | P35: Concluido | Q35: 1 | R35: 1 | S35: 102 | T35: PROCESSO INDUSTRIAL | U35: 45489 | V35: QUANDO NECESSARIO | X35: =IF(Tabela1[[#This Row],[DATA_CURSO]]="", "PENDENTE", IF(Tabela1[[#This Row],[TIPO_RENOVACAO]]="QUANDO NECESSARIO", "EM DIA – não é necessário renovar", IFERROR( IF(SUM(Tabela1[[#This Row],[DATA_CURSO]],VLOOKUP(Tabela1[[#This Row],[DESCRICAO]],RENOVAÇÃO!A:C,3,0))<TODAY(), "VENCIDO – "&TEXT(SUM(Tabela1[[#This Row],[DATA_CURSO]],VLOOKUP(Tabela1[[#This Row],[DESCRICAO]],RENOVAÇÃO!A:C,3,0)),"dd/mm/aa"), "EM DIA – vence em "&TEXT(SUM(Tabela1[[#This Row],[DATA_CURSO]],VLOOKUP(Tabela1[[#This Row],[DESCRICAO]],RENOVAÇÃO!A:C,3,0)),"dd/mm/aa")), "NÃO É NECESSÁRIO RENOVAR"))) -> EM DIA – não é necessário renovar | Y35: =IF(Tabela1[[#This Row],[FILIAL]]=1,"SINOP",IF(Tabela1[[#This Row],[FILIAL]]=2,"DOURADOS",IF(Tabela1[[#This Row],[FILIAL]]=3,"NOVA MUTUM",IF(Tabela1[[#This Row],[FILIAL]]=4,"FULLING",IF(Tabela1[[#This Row],[FILIAL]]=5,"SÃO PAULO",IF(Tabela1[[#This Row],[FILIAL]]=6,"SIDROLÂNDIA",IF(Tabela1[[#This Row],[FILIAL]]=8,"BALSAS",IF(Tabela1[[#This Row],[FILIAL]]=10,"LUIS EDUARDO MAGALHÃES","")))))))) -> SINOP | Z35: =VLOOKUP(N35,RENOVAÇÃO!A:D,4,0) -> TRILHA SEGURANÇA DO TRABALHO | AA35: =CONCATENATE("• ", Tabela1[[#This Row],[DESCRICAO]], " - ",Tabela1[[#This Row],[STATUS_GERAL]]) -> • NR 26 - SINALIZAÇÃO DE SEGURANÇA - EM DIA – não é necessário renovar
